// Copyright (c) Rackspace, US Inc. All Rights Reserved. Licensed under the Apache License, Version 2.0. See LICENSE in the project root for license information.

namespace UnitTest.RackspaceThreading
{
    using System;
    using System.Collections.Generic;
    using System.Threading.Tasks;
    using Microsoft.VisualStudio.TestTools.UnitTesting;
    using Rackspace.Threading;

    [TestClass]
    public class TestCoreTaskExtensions_Select
    {
        #region Select 1

        /// <summary>
        /// This method test the behavior of the
        /// <see cref="CoreTaskExtensions.Select(Task, Action{Task})"/>
        /// method.
        /// </summary>
        [TestMethod]
        [ExpectedException(typeof(ArgumentNullException))]
        public void TestSelect1_NullAntecedent_CompletedContinuation()
        {
            // declaring these makes it clear we are testing the correct overload
            Task antecedent = null;
            Action<Task> continuationAction = task =>
                {
                };

            CoreTaskExtensions.Select(antecedent, continuationAction);
        }

        /// <summary>
        /// This method test the behavior of the
        /// <see cref="CoreTaskExtensions.Select(Task, Action{Task})"/>
        /// method.
        /// </summary>
        [TestMethod]
        [ExpectedException(typeof(ArgumentNullException))]
        public void TestSelect1_CompletedAntecedent_NullContinuation()
        {
            // declaring these makes it clear we are testing the correct overload
            Task antecedent = CompletedTask.Default;
            Action<Task> continuationAction = null;

            CoreTaskExtensions.Select(antecedent, continuationAction);
        }

        /// <summary>
        /// This method test the behavior of the
        /// <see cref="CoreTaskExtensions.Select(Task, Action{Task})"/>
        /// method.
        /// </summary>
        [TestMethod]
        public void TestSelect1_CompletedAntecedent_CompletedContinuation()
        {
            bool executed = false;

            // declaring these makes it clear we are testing the correct overload
            Task antecedent = CompletedTask.Default;
            Action<Task> continuationAction = task => executed = true;

            Task combinedTask = CoreTaskExtensions.Select(antecedent, continuationAction);
            combinedTask.Wait();
            Assert.AreEqual(TaskStatus.RanToCompletion, combinedTask.Status);
            Assert.IsTrue(executed);
        }

        /// <summary>
        /// This method test the behavior of the
        /// <see cref="CoreTaskExtensions.Select(Task, Action{Task})"/>
        /// method.
        /// </summary>
        [TestMethod]
        public void TestSelect1_CanceledAntecedent_CompletedContinuation()
        {
            bool executed = false;

            // declaring these makes it clear we are testing the correct overload
            Task antecedent = CompletedTask.Canceled();
            Action<Task> continuationAction = task => executed = true;

            Task combinedTask = null;

            try
            {
                combinedTask = CoreTaskExtensions.Select(antecedent, continuationAction);
                combinedTask.Wait();
                Assert.Fail("Expected a TaskCanceledException wrapped in an AggregateException");
            }
            catch (AggregateException ex)
            {
                Assert.IsNotNull(combinedTask, "Failed to create the combined task.");
                Assert.AreEqual(TaskStatus.Canceled, combinedTask.Status);
                Assert.AreEqual(1, ex.InnerExceptions.Count);
                Assert.IsInstanceOfType(ex.InnerExceptions[0], typeof(TaskCanceledException));
                Assert.IsFalse(executed);
            }
        }

        /// <summary>
        /// This method test the behavior of the
        /// <see cref="CoreTaskExtensions.Select(Task, Action{Task})"/>
        /// method.
        /// </summary>
        [TestMethod]
        public void TestSelect1_FaultedAntecedent_CompletedContinuation()
        {
            bool executed = false;

            // declaring these makes it clear we are testing the correct overload
            TaskCompletionSource<object> faultedCompletionSource = new TaskCompletionSource<object>();
            Exception expectedException = new ArgumentException();
            faultedCompletionSource.SetException(expectedException);
            Task antecedent = faultedCompletionSource.Task;
            Action<Task> continuationAction = task => executed = true;

            Task combinedTask = null;

            try
            {
                combinedTask = CoreTaskExtensions.Select(antecedent, continuationAction);
                combinedTask.Wait();
                Assert.Fail("Expected an ArgumentException wrapped in an AggregateException");
            }
            catch (AggregateException ex)
            {
                Assert.IsNotNull(combinedTask, "Failed to create the combined task.");
                Assert.AreEqual(TaskStatus.Faulted, combinedTask.Status);
                Assert.AreEqual(1, ex.InnerExceptions.Count);
                Assert.AreSame(expectedException, ex.InnerExceptions[0]);
                Assert.IsFalse(executed);
            }
        }

        /// <summary>
        /// This method test the behavior of the
        /// <see cref="CoreTaskExtensions.Select(Task, Action{Task})"/>
        /// method.
        /// </summary>
        [TestMethod]
        public void TestSelect1_CompletedAntecedent_FaultedContinuation()
        {
            bool executed = false;

            // declaring these makes it clear we are testing the correct overload
            Task antecedent = CompletedTask.Default;

            Exception continuationException = new InvalidOperationException();
            Action<Task> continuationAction = task =>
                {
                    executed = true;
                    throw continuationException;
                };

            Task combinedTask = null;

            try
            {
                combinedTask = CoreTaskExtensions.Select(antecedent, continuationAction);
                combinedTask.Wait();
                Assert.Fail("Expected an InvalidOperationException wrapped in an AggregateException");
            }
            catch (AggregateException ex)
            {
                Assert.IsNotNull(combinedTask, "Failed to create the combined task.");
                Assert.AreEqual(TaskStatus.Faulted, combinedTask.Status);
                Assert.AreEqual(1, ex.InnerExceptions.Count);
                Assert.AreSame(continuationException, ex.InnerExceptions[0]);
                Assert.IsTrue(executed);
            }
        }

        /// <summary>
        /// This method test the behavior of the
        /// <see cref="CoreTaskExtensions.Select(Task, Action{Task})"/>
        /// method.
        /// </summary>
        [TestMethod]
        public void TestSelect1_CanceledAntecedent_FaultedContinuation()
        {
            bool executed = false;

            // declaring these makes it clear we are testing the correct overload
            Task antecedent = CompletedTask.Canceled();

            Exception continuationException = new InvalidOperationException();
            Action<Task> continuationAction = task =>
                {
                    executed = true;
                    throw continuationException;
                };

            Task combinedTask = null;

            try
            {
                combinedTask = CoreTaskExtensions.Select(antecedent, continuationAction);
                combinedTask.Wait();
                Assert.Fail("Expected a TaskCanceledException wrapped in an AggregateException");
            }
            catch (AggregateException ex)
            {
                Assert.IsNotNull(combinedTask, "Failed to create the combined task.");
                Assert.AreEqual(TaskStatus.Canceled, combinedTask.Status);
                Assert.AreEqual(1, ex.InnerExceptions.Count);
                Assert.IsInstanceOfType(ex.InnerExceptions[0], typeof(TaskCanceledException));
                Assert.IsFalse(executed);
            }
        }

        /// <summary>
        /// This method test the behavior of the
        /// <see cref="CoreTaskExtensions.Select(Task, Action{Task})"/>
        /// method.
        /// </summary>
        [TestMethod]
        public void TestSelect1_FaultedAntecedent_FaultedContinuation()
        {
            bool executed = false;

            // declaring these makes it clear we are testing the correct overload
            TaskCompletionSource<object> faultedCompletionSource = new TaskCompletionSource<object>();
            Exception expectedException = new ArgumentException();
            faultedCompletionSource.SetException(expectedException);
            Task antecedent = faultedCompletionSource.Task;

            Exception continuationException = new InvalidOperationException();
            Action<Task> continuationAction = task =>
                {
                    executed = true;
                    throw continuationException;
                };

            Task combinedTask = null;

            try
            {
                combinedTask = CoreTaskExtensions.Select(antecedent, continuationAction);
                combinedTask.Wait();
                Assert.Fail("Expected an ArgumentException wrapped in an AggregateException");
            }
            catch (AggregateException ex)
            {
                Assert.IsNotNull(combinedTask, "Failed to create the combined task.");
                Assert.AreEqual(TaskStatus.Faulted, combinedTask.Status);
                Assert.AreEqual(1, ex.InnerExceptions.Count);
                Assert.AreSame(expectedException, ex.InnerExceptions[0]);
                Assert.IsFalse(executed);
            }
        }

        #endregion

        #region Select 2

        /// <summary>
        /// This method test the behavior of the
        /// <see cref="CoreTaskExtensions.Select(Task, Action{Task}, bool)"/>
        /// method.
        /// </summary>
        [TestMethod]
        [ExpectedException(typeof(ArgumentNullException))]
        public void TestSelect2_NullAntecedent_CompletedContinuation_NoErrors()
        {
            // declaring these makes it clear we are testing the correct overload
            Task antecedent = null;
            Action<Task> continuationAction = task =>
                {
                };
            bool supportsErrors = false;

            CoreTaskExtensions.Select(antecedent, continuationAction, supportsErrors);
        }

        /// <summary>
        /// This method test the behavior of the
        /// <see cref="CoreTaskExtensions.Select(Task, Action{Task}, bool)"/>
        /// method.
        /// </summary>
        [TestMethod]
        [ExpectedException(typeof(ArgumentNullException))]
        public void TestSelect2_CompletedAntecedent_NullContinuation_NoErrors()
        {
            // declaring these makes it clear we are testing the correct overload
            Task antecedent = CompletedTask.Default;
            Action<Task> continuationAction = null;
            bool supportsErrors = false;

            CoreTaskExtensions.Select(antecedent, continuationAction, supportsErrors);
        }

        /// <summary>
        /// This method test the behavior of the
        /// <see cref="CoreTaskExtensions.Select(Task, Action{Task}, bool)"/>
        /// method.
        /// </summary>
        [TestMethod]
        public void TestSelect2_CompletedAntecedent_CompletedContinuation_NoErrors()
        {
            bool executed = false;

            // declaring these makes it clear we are testing the correct overload
            Task antecedent = CompletedTask.Default;
            Action<Task> continuationAction = task => executed = true;
            bool supportsErrors = false;

            Task combinedTask = CoreTaskExtensions.Select(antecedent, continuationAction, supportsErrors);
            combinedTask.Wait();
            Assert.AreEqual(TaskStatus.RanToCompletion, combinedTask.Status);
            Assert.IsTrue(executed);
        }

        /// <summary>
        /// This method test the behavior of the
        /// <see cref="CoreTaskExtensions.Select(Task, Action{Task}, bool)"/>
        /// method.
        /// </summary>
        [TestMethod]
        public void TestSelect2_CanceledAntecedent_CompletedContinuation_NoErrors()
        {
            bool executed = false;

            // declaring these makes it clear we are testing the correct overload
            Task antecedent = CompletedTask.Canceled();
            Action<Task> continuationAction = task => executed = true;
            bool supportsErrors = false;

            Task combinedTask = null;

            try
            {
                combinedTask = CoreTaskExtensions.Select(antecedent, continuationAction, supportsErrors);
                combinedTask.Wait();
                Assert.Fail("Expected a TaskCanceledException wrapped in an AggregateException");
            }
            catch (AggregateException ex)
            {
                Assert.IsNotNull(combinedTask, "Failed to create the combined task.");
                Assert.AreEqual(TaskStatus.Canceled, combinedTask.Status);
                Assert.AreEqual(1, ex.InnerExceptions.Count);
                Assert.IsInstanceOfType(ex.InnerExceptions[0], typeof(TaskCanceledException));
                Assert.IsFalse(executed);
            }
        }

        /// <summary>
        /// This method test the behavior of the
        /// <see cref="CoreTaskExtensions.Select(Task, Action{Task}, bool)"/>
        /// method.
        /// </summary>
        [TestMethod]
        public void TestSelect2_FaultedAntecedent_CompletedContinuation_NoErrors()
        {
            bool executed = false;

            // declaring these makes it clear we are testing the correct overload
            TaskCompletionSource<object> faultedCompletionSource = new TaskCompletionSource<object>();
            Exception expectedException = new ArgumentException();
            faultedCompletionSource.SetException(expectedException);
            Task antecedent = faultedCompletionSource.Task;
            Action<Task> continuationAction = task => executed = true;
            bool supportsErrors = false;

            Task combinedTask = null;

            try
            {
                combinedTask = CoreTaskExtensions.Select(antecedent, continuationAction, supportsErrors);
                combinedTask.Wait();
                Assert.Fail("Expected an ArgumentException wrapped in an AggregateException");
            }
            catch (AggregateException ex)
            {
                Assert.IsNotNull(combinedTask, "Failed to create the combined task.");
                Assert.AreEqual(TaskStatus.Faulted, combinedTask.Status);
                Assert.AreEqual(1, ex.InnerExceptions.Count);
                Assert.AreSame(expectedException, ex.InnerExceptions[0]);
                Assert.IsFalse(executed);
            }
        }

        /// <summary>
        /// This method test the behavior of the
        /// <see cref="CoreTaskExtensions.Select(Task, Action{Task}, bool)"/>
        /// method.
        /// </summary>
        [TestMethod]
        public void TestSelect2_CompletedAntecedent_FaultedContinuation_NoErrors()
        {
            bool executed = false;

            // declaring these makes it clear we are testing the correct overload
            Task antecedent = CompletedTask.Default;

            Exception continuationException = new InvalidOperationException();
            Action<Task> continuationAction = task =>
                {
                    executed = true;
                    throw continuationException;
                };

            bool supportsErrors = false;

            Task combinedTask = null;

            try
            {
                combinedTask = CoreTaskExtensions.Select(antecedent, continuationAction, supportsErrors);
                combinedTask.Wait();
                Assert.Fail("Expected an InvalidOperationException wrapped in an AggregateException");
            }
            catch (AggregateException ex)
            {
                Assert.IsNotNull(combinedTask, "Failed to create the combined task.");
                Assert.AreEqual(TaskStatus.Faulted, combinedTask.Status);
                Assert.AreEqual(1, ex.InnerExceptions.Count);
                Assert.AreSame(continuationException, ex.InnerExceptions[0]);
                Assert.IsTrue(executed);
            }
        }

        /// <summary>
        /// This method test the behavior of the
        /// <see cref="CoreTaskExtensions.Select(Task, Action{Task}, bool)"/>
        /// method.
        /// </summary>
        [TestMethod]
        public void TestSelect2_CanceledAntecedent_FaultedContinuation_NoErrors()
        {
            bool executed = false;

            // declaring these makes it clear we are testing the correct overload
            Task antecedent = CompletedTask.Canceled();

            Exception continuationException = new InvalidOperationException();
            Action<Task> continuationAction = task =>
                {
                    executed = true;
                    throw continuationException;
                };

            bool supportsErrors = false;

            Task combinedTask = null;

            try
            {
                combinedTask = CoreTaskExtensions.Select(antecedent, continuationAction, supportsErrors);
                combinedTask.Wait();
                Assert.Fail("Expected a TaskCanceledException wrapped in an AggregateException");
            }
            catch (AggregateException ex)
            {
                Assert.IsNotNull(combinedTask, "Failed to create the combined task.");
                Assert.AreEqual(TaskStatus.Canceled, combinedTask.Status);
                Assert.AreEqual(1, ex.InnerExceptions.Count);
                Assert.IsInstanceOfType(ex.InnerExceptions[0], typeof(TaskCanceledException));
                Assert.IsFalse(executed);
            }
        }

        /// <summary>
        /// This method test the behavior of the
        /// <see cref="CoreTaskExtensions.Select(Task, Action{Task}, bool)"/>
        /// method.
        /// </summary>
        [TestMethod]
        public void TestSelect2_FaultedAntecedent_FaultedContinuation_NoErrors()
        {
            bool executed = false;

            // declaring these makes it clear we are testing the correct overload
            TaskCompletionSource<object> faultedCompletionSource = new TaskCompletionSource<object>();
            Exception expectedException = new ArgumentException();
            faultedCompletionSource.SetException(expectedException);
            Task antecedent = faultedCompletionSource.Task;

            Exception continuationException = new InvalidOperationException();
            Action<Task> continuationAction = task =>
                {
                    executed = true;
                    throw continuationException;
                };

            bool supportsErrors = false;

            Task combinedTask = null;

            try
            {
                combinedTask = CoreTaskExtensions.Select(antecedent, continuationAction, supportsErrors);
                combinedTask.Wait();
                Assert.Fail("Expected an ArgumentException wrapped in an AggregateException");
            }
            catch (AggregateException ex)
            {
                Assert.IsNotNull(combinedTask, "Failed to create the combined task.");
                Assert.AreEqual(TaskStatus.Faulted, combinedTask.Status);
                Assert.AreEqual(1, ex.InnerExceptions.Count);
                Assert.AreSame(expectedException, ex.InnerExceptions[0]);
                Assert.IsFalse(executed);
            }
        }

        /// <summary>
        /// This method test the behavior of the
        /// <see cref="CoreTaskExtensions.Select(Task, Action{Task}, bool)"/>
        /// method.
        /// </summary>
        [TestMethod]
        [ExpectedException(typeof(ArgumentNullException))]
        public void TestSelect2_NullAntecedent_CompletedContinuation_SupportsErrors()
        {
            // declaring these makes it clear we are testing the correct overload
            Task antecedent = null;
            Action<Task> continuationAction = task =>
                {
                };
            bool supportsErrors = true;

            CoreTaskExtensions.Select(antecedent, continuationAction, supportsErrors);
        }

        /// <summary>
        /// This method test the behavior of the
        /// <see cref="CoreTaskExtensions.Select(Task, Action{Task}, bool)"/>
        /// method.
        /// </summary>
        [TestMethod]
        [ExpectedException(typeof(ArgumentNullException))]
        public void TestSelect2_CompletedAntecedent_NullContinuation_SupportsErrors()
        {
            // declaring these makes it clear we are testing the correct overload
            Task antecedent = CompletedTask.Default;
            Action<Task> continuationAction = null;
            bool supportsErrors = true;

            CoreTaskExtensions.Select(antecedent, continuationAction, supportsErrors);
        }

        /// <summary>
        /// This method test the behavior of the
        /// <see cref="CoreTaskExtensions.Select(Task, Action{Task}, bool)"/>
        /// method.
        /// </summary>
        [TestMethod]
        public void TestSelect2_CompletedAntecedent_CompletedContinuation_SupportsErrors()
        {
            bool executed = false;

            // declaring these makes it clear we are testing the correct overload
            Task antecedent = CompletedTask.Default;
            Action<Task> continuationAction = task => executed = true;
            bool supportsErrors = true;

            Task combinedTask = CoreTaskExtensions.Select(antecedent, continuationAction, supportsErrors);
            combinedTask.Wait();
            Assert.AreEqual(TaskStatus.RanToCompletion, combinedTask.Status);
            Assert.IsTrue(executed);
        }

        /// <summary>
        /// This method test the behavior of the
        /// <see cref="CoreTaskExtensions.Select(Task, Action{Task}, bool)"/>
        /// method.
        /// </summary>
        [TestMethod]
        public void TestSelect2_CanceledAntecedent_CompletedContinuation_SupportsErrors()
        {
            bool executed = false;

            // declaring these makes it clear we are testing the correct overload
            Task antecedent = CompletedTask.Canceled();
            Action<Task> continuationAction = task => executed = true;
            bool supportsErrors = true;

            Task combinedTask = null;

            try
            {
                combinedTask = CoreTaskExtensions.Select(antecedent, continuationAction, supportsErrors);
                combinedTask.Wait();
                Assert.Fail("Expected a TaskCanceledException wrapped in an AggregateException");
            }
            catch (AggregateException ex)
            {
                Assert.IsNotNull(combinedTask, "Failed to create the combined task.");
                Assert.AreEqual(TaskStatus.Canceled, combinedTask.Status);
                Assert.AreEqual(1, ex.InnerExceptions.Count);
                Assert.IsInstanceOfType(ex.InnerExceptions[0], typeof(TaskCanceledException));
                Assert.IsFalse(executed);
            }
        }

        /// <summary>
        /// This method test the behavior of the
        /// <see cref="CoreTaskExtensions.Select(Task, Action{Task}, bool)"/>
        /// method.
        /// </summary>
        [TestMethod]
        public void TestSelect2_FaultedAntecedent_CompletedContinuation_SupportsErrors()
        {
            bool executed = false;

            // declaring these makes it clear we are testing the correct overload
            TaskCompletionSource<object> faultedCompletionSource = new TaskCompletionSource<object>();
            Exception expectedException = new ArgumentException();
            faultedCompletionSource.SetException(expectedException);
            Task antecedent = faultedCompletionSource.Task;
            Action<Task> continuationAction = task => executed = true;
            bool supportsErrors = true;

            Task combinedTask = CoreTaskExtensions.Select(antecedent, continuationAction, supportsErrors);
            combinedTask.Wait();
            Assert.AreEqual(TaskStatus.RanToCompletion, combinedTask.Status);
            Assert.IsTrue(executed);
        }

        /// <summary>
        /// This method test the behavior of the
        /// <see cref="CoreTaskExtensions.Select(Task, Action{Task}, bool)"/>
        /// method.
        /// </summary>
        [TestMethod]
        public void TestSelect2_CompletedAntecedent_FaultedContinuation_SupportsErrors()
        {
            bool executed = false;

            // declaring these makes it clear we are testing the correct overload
            Task antecedent = CompletedTask.Default;

            Exception continuationException = new InvalidOperationException();
            Action<Task> continuationAction = task =>
                {
                    executed = true;
                    throw continuationException;
                };

            bool supportsErrors = true;

            Task combinedTask = null;

            try
            {
                combinedTask = CoreTaskExtensions.Select(antecedent, continuationAction, supportsErrors);
                combinedTask.Wait();
                Assert.Fail("Expected an InvalidOperationException wrapped in an AggregateException");
            }
            catch (AggregateException ex)
            {
                Assert.IsNotNull(combinedTask, "Failed to create the combined task.");
                Assert.AreEqual(TaskStatus.Faulted, combinedTask.Status);
                Assert.AreEqual(1, ex.InnerExceptions.Count);
                Assert.AreSame(continuationException, ex.InnerExceptions[0]);
                Assert.IsTrue(executed);
            }
        }

        /// <summary>
        /// This method test the behavior of the
        /// <see cref="CoreTaskExtensions.Select(Task, Action{Task}, bool)"/>
        /// method.
        /// </summary>
        [TestMethod]
        public void TestSelect2_CanceledAntecedent_FaultedContinuation_SupportsErrors()
        {
            bool executed = false;

            // declaring these makes it clear we are testing the correct overload
            Task antecedent = CompletedTask.Canceled();

            Exception continuationException = new InvalidOperationException();
            Action<Task> continuationAction = task =>
                {
                    executed = true;
                    throw continuationException;
                };

            bool supportsErrors = true;

            Task combinedTask = null;

            try
            {
                combinedTask = CoreTaskExtensions.Select(antecedent, continuationAction, supportsErrors);
                combinedTask.Wait();
                Assert.Fail("Expected a TaskCanceledException wrapped in an AggregateException");
            }
            catch (AggregateException ex)
            {
                Assert.IsNotNull(combinedTask, "Failed to create the combined task.");
                Assert.AreEqual(TaskStatus.Canceled, combinedTask.Status);
                Assert.AreEqual(1, ex.InnerExceptions.Count);
                Assert.IsInstanceOfType(ex.InnerExceptions[0], typeof(TaskCanceledException));
                Assert.IsFalse(executed);
            }
        }

        /// <summary>
        /// This method test the behavior of the
        /// <see cref="CoreTaskExtensions.Select(Task, Action{Task}, bool)"/>
        /// method.
        /// </summary>
        [TestMethod]
        public void TestSelect2_FaultedAntecedent_FaultedContinuation_SupportsErrors()
        {
            bool executed = false;

            // declaring these makes it clear we are testing the correct overload
            TaskCompletionSource<object> faultedCompletionSource = new TaskCompletionSource<object>();
            Exception expectedException = new ArgumentException();
            faultedCompletionSource.SetException(expectedException);
            Task antecedent = faultedCompletionSource.Task;

            Exception continuationException = new InvalidOperationException();
            Action<Task> continuationAction = task =>
                {
                    executed = true;
                    throw continuationException;
                };

            bool supportsErrors = true;

            Task combinedTask = null;

            try
            {
                combinedTask = CoreTaskExtensions.Select(antecedent, continuationAction, supportsErrors);
                combinedTask.Wait();
                Assert.Fail("Expected an InvalidOperationException wrapped in an AggregateException");
            }
            catch (AggregateException ex)
            {
                Assert.IsNotNull(combinedTask, "Failed to create the combined task.");
                Assert.AreEqual(TaskStatus.Faulted, combinedTask.Status);
                Assert.AreEqual(1, ex.InnerExceptions.Count);
                Assert.AreSame(continuationException, ex.InnerExceptions[0]);
                Assert.IsTrue(executed);
            }
        }

        #endregion

        #region Select 3

        /// <summary>
        /// This method test the behavior of the
        /// <see cref="CoreTaskExtensions.Select{TResult}(Task, Func{Task, TResult})"/>
        /// method.
        /// </summary>
        [TestMethod]
        [ExpectedException(typeof(ArgumentNullException))]
        public void TestSelect3_NullAntecedent_CompletedContinuation()
        {
            // declaring these makes it clear we are testing the correct overload
            Task antecedent = null;
            object result = new object();
            Func<Task, object> continuationFunction = task => result;

            CoreTaskExtensions.Select(antecedent, continuationFunction);
        }

        /// <summary>
        /// This method test the behavior of the
        /// <see cref="CoreTaskExtensions.Select{TResult}(Task, Func{Task, TResult})"/>
        /// method.
        /// </summary>
        [TestMethod]
        [ExpectedException(typeof(ArgumentNullException))]
        public void TestSelect3_CompletedAntecedent_NullContinuation()
        {
            // declaring these makes it clear we are testing the correct overload
            Task antecedent = CompletedTask.Default;
            Func<Task, object> continuationFunction = null;

            CoreTaskExtensions.Select(antecedent, continuationFunction);
        }

        /// <summary>
        /// This method test the behavior of the
        /// <see cref="CoreTaskExtensions.Select{TResult}(Task, Func{Task, TResult})"/>
        /// method.
        /// </summary>
        [TestMethod]
        public void TestSelect3_CompletedAntecedent_CompletedContinuation()
        {
            bool executed = false;

            // declaring these makes it clear we are testing the correct overload
            Task antecedent = CompletedTask.Default;
            object result = new object();
            Func<Task, object> continuationFunction = task =>
                {
                    executed = true;
                    return result;
                };

            Task<object> combinedTask = CoreTaskExtensions.Select(antecedent, continuationFunction);
            combinedTask.Wait();
            Assert.AreEqual(TaskStatus.RanToCompletion, combinedTask.Status);
            Assert.AreSame(result, combinedTask.Result);
            Assert.IsTrue(executed);
        }

        /// <summary>
        /// This method test the behavior of the
        /// <see cref="CoreTaskExtensions.Select{TResult}(Task, Func{Task, TResult})"/>
        /// method.
        /// </summary>
        [TestMethod]
        public void TestSelect3_CanceledAntecedent_CompletedContinuation()
        {
            bool executed = false;

            // declaring these makes it clear we are testing the correct overload
            Task antecedent = CompletedTask.Canceled();
            object result = new object();
            Func<Task, object> continuationFunction = task =>
                {
                    executed = true;
                    return result;
                };

            Task<object> combinedTask = null;

            try
            {
                combinedTask = CoreTaskExtensions.Select(antecedent, continuationFunction);
                combinedTask.Wait();
                Assert.Fail("Expected a TaskCanceledException wrapped in an AggregateException");
            }
            catch (AggregateException ex)
            {
                Assert.IsNotNull(combinedTask, "Failed to create the combined task.");
                Assert.AreEqual(TaskStatus.Canceled, combinedTask.Status);
                Assert.AreEqual(1, ex.InnerExceptions.Count);
                Assert.IsInstanceOfType(ex.InnerExceptions[0], typeof(TaskCanceledException));
                Assert.IsFalse(executed);
            }
        }

        /// <summary>
        /// This method test the behavior of the
        /// <see cref="CoreTaskExtensions.Select{TResult}(Task, Func{Task, TResult})"/>
        /// method.
        /// </summary>
        [TestMethod]
        public void TestSelect3_FaultedAntecedent_CompletedContinuation()
        {
            bool executed = false;

            // declaring these makes it clear we are testing the correct overload
            TaskCompletionSource<object> faultedCompletionSource = new TaskCompletionSource<object>();
            Exception expectedException = new ArgumentException();
            faultedCompletionSource.SetException(expectedException);
            Task antecedent = faultedCompletionSource.Task;
            object result = new object();
            Func<Task, object> continuationFunction = task =>
                {
                    executed = true;
                    return result;
                };

            Task<object> combinedTask = null;

            try
            {
                combinedTask = CoreTaskExtensions.Select(antecedent, continuationFunction);
                combinedTask.Wait();
                Assert.Fail("Expected an ArgumentException wrapped in an AggregateException");
            }
            catch (AggregateException ex)
            {
                Assert.IsNotNull(combinedTask, "Failed to create the combined task.");
                Assert.AreEqual(TaskStatus.Faulted, combinedTask.Status);
                Assert.AreEqual(1, ex.InnerExceptions.Count);
                Assert.AreSame(expectedException, ex.InnerExceptions[0]);
                Assert.IsFalse(executed);
            }
        }

        /// <summary>
        /// This method test the behavior of the
        /// <see cref="CoreTaskExtensions.Select{TResult}(Task, Func{Task, TResult})"/>
        /// method.
        /// </summary>
        [TestMethod]
        public void TestSelect3_CompletedAntecedent_FaultedContinuation()
        {
            bool executed = false;

            // declaring these makes it clear we are testing the correct overload
            Task antecedent = CompletedTask.Default;

            Exception continuationException = new InvalidOperationException();
            Func<Task, object> continuationFunction = task =>
                {
                    executed = true;
                    throw continuationException;
                };

            Task<object> combinedTask = null;

            try
            {
                combinedTask = CoreTaskExtensions.Select(antecedent, continuationFunction);
                combinedTask.Wait();
                Assert.Fail("Expected an InvalidOperationException wrapped in an AggregateException");
            }
            catch (AggregateException ex)
            {
                Assert.IsNotNull(combinedTask, "Failed to create the combined task.");
                Assert.AreEqual(TaskStatus.Faulted, combinedTask.Status);
                Assert.AreEqual(1, ex.InnerExceptions.Count);
                Assert.AreSame(continuationException, ex.InnerExceptions[0]);
                Assert.IsTrue(executed);
            }
        }

        /// <summary>
        /// This method test the behavior of the
        /// <see cref="CoreTaskExtensions.Select{TResult}(Task, Func{Task, TResult})"/>
        /// method.
        /// </summary>
        [TestMethod]
        public void TestSelect3_CanceledAntecedent_FaultedContinuation()
        {
            bool executed = false;

            // declaring these makes it clear we are testing the correct overload
            Task antecedent = CompletedTask.Canceled();

            Exception continuationException = new InvalidOperationException();
            Func<Task, object> continuationFunction = task =>
                {
                    executed = true;
                    throw continuationException;
                };

            Task<object> combinedTask = null;

            try
            {
                combinedTask = CoreTaskExtensions.Select(antecedent, continuationFunction);
                combinedTask.Wait();
                Assert.Fail("Expected a TaskCanceledException wrapped in an AggregateException");
            }
            catch (AggregateException ex)
            {
                Assert.IsNotNull(combinedTask, "Failed to create the combined task.");
                Assert.AreEqual(TaskStatus.Canceled, combinedTask.Status);
                Assert.AreEqual(1, ex.InnerExceptions.Count);
                Assert.IsInstanceOfType(ex.InnerExceptions[0], typeof(TaskCanceledException));
                Assert.IsFalse(executed);
            }
        }

        /// <summary>
        /// This method test the behavior of the
        /// <see cref="CoreTaskExtensions.Select{TResult}(Task, Func{Task, TResult})"/>
        /// method.
        /// </summary>
        [TestMethod]
        public void TestSelect3_FaultedAntecedent_FaultedContinuation()
        {
            bool executed = false;

            // declaring these makes it clear we are testing the correct overload
            TaskCompletionSource<object> faultedCompletionSource = new TaskCompletionSource<object>();
            Exception expectedException = new ArgumentException();
            faultedCompletionSource.SetException(expectedException);
            Task antecedent = faultedCompletionSource.Task;

            Exception continuationException = new InvalidOperationException();
            Func<Task, object> continuationFunction = task =>
                {
                    executed = true;
                    throw continuationException;
                };

            Task<object> combinedTask = null;

            try
            {
                combinedTask = CoreTaskExtensions.Select(antecedent, continuationFunction);
                combinedTask.Wait();
                Assert.Fail("Expected an ArgumentException wrapped in an AggregateException");
            }
            catch (AggregateException ex)
            {
                Assert.IsNotNull(combinedTask, "Failed to create the combined task.");
                Assert.AreEqual(TaskStatus.Faulted, combinedTask.Status);
                Assert.AreEqual(1, ex.InnerExceptions.Count);
                Assert.AreSame(expectedException, ex.InnerExceptions[0]);
                Assert.IsFalse(executed);
            }
        }

        #endregion

        #region Select 4

        /// <summary>
        /// This method test the behavior of the
        /// <see cref="CoreTaskExtensions.Select{TResult}(Task, Func{Task, TResult}, bool)"/>
        /// method.
        /// </summary>
        [TestMethod]
        [ExpectedException(typeof(ArgumentNullException))]
        public void TestSelect4_NullAntecedent_CompletedContinuation_NoErrors()
        {
            // declaring these makes it clear we are testing the correct overload
            Task antecedent = null;
            object result = new object();
            Func<Task, object> continuationFunction = task => result;

            bool supportsErrors = false;

            CoreTaskExtensions.Select(antecedent, continuationFunction, supportsErrors);
        }

        /// <summary>
        /// This method test the behavior of the
        /// <see cref="CoreTaskExtensions.Select{TResult}(Task, Func{Task, TResult}, bool)"/>
        /// method.
        /// </summary>
        [TestMethod]
        [ExpectedException(typeof(ArgumentNullException))]
        public void TestSelect4_CompletedAntecedent_NullContinuation_NoErrors()
        {
            // declaring these makes it clear we are testing the correct overload
            Task antecedent = CompletedTask.Default;
            Func<Task, object> continuationFunction = null;

            bool supportsErrors = false;

            CoreTaskExtensions.Select(antecedent, continuationFunction, supportsErrors);
        }

        /// <summary>
        /// This method test the behavior of the
        /// <see cref="CoreTaskExtensions.Select{TResult}(Task, Func{Task, TResult}, bool)"/>
        /// method.
        /// </summary>
        [TestMethod]
        public void TestSelect4_CompletedAntecedent_CompletedContinuation_NoErrors()
        {
            bool executed = false;

            // declaring these makes it clear we are testing the correct overload
            Task antecedent = CompletedTask.Default;
            object result = new object();
            Func<Task, object> continuationFunction = task =>
                {
                    executed = true;
                    return result;
                };

            bool supportsErrors = false;

            Task<object> combinedTask = CoreTaskExtensions.Select(antecedent, continuationFunction, supportsErrors);
            combinedTask.Wait();
            Assert.AreEqual(TaskStatus.RanToCompletion, combinedTask.Status);
            Assert.AreSame(result, combinedTask.Result);
            Assert.IsTrue(executed);
        }

        /// <summary>
        /// This method test the behavior of the
        /// <see cref="CoreTaskExtensions.Select{TResult}(Task, Func{Task, TResult}, bool)"/>
        /// method.
        /// </summary>
        [TestMethod]
        public void TestSelect4_CanceledAntecedent_CompletedContinuation_NoErrors()
        {
            bool executed = false;

            // declaring these makes it clear we are testing the correct overload
            Task antecedent = CompletedTask.Canceled();
            object result = new object();
            Func<Task, object> continuationFunction = task =>
                {
                    executed = true;
                    return result;
                };

            bool supportsErrors = false;

            Task<object> combinedTask = null;

            try
            {
                combinedTask = CoreTaskExtensions.Select(antecedent, continuationFunction, supportsErrors);
                combinedTask.Wait();
                Assert.Fail("Expected a TaskCanceledException wrapped in an AggregateException");
            }
            catch (AggregateException ex)
            {
                Assert.IsNotNull(combinedTask, "Failed to create the combined task.");
                Assert.AreEqual(TaskStatus.Canceled, combinedTask.Status);
                Assert.AreEqual(1, ex.InnerExceptions.Count);
                Assert.IsInstanceOfType(ex.InnerExceptions[0], typeof(TaskCanceledException));
                Assert.IsFalse(executed);
            }
        }

        /// <summary>
        /// This method test the behavior of the
        /// <see cref="CoreTaskExtensions.Select{TResult}(Task, Func{Task, TResult}, bool)"/>
        /// method.
        /// </summary>
        [TestMethod]
        public void TestSelect4_FaultedAntecedent_CompletedContinuation_NoErrors()
        {
            bool executed = false;

            // declaring these makes it clear we are testing the correct overload
            TaskCompletionSource<object> faultedCompletionSource = new TaskCompletionSource<object>();
            Exception expectedException = new ArgumentException();
            faultedCompletionSource.SetException(expectedException);
            Task antecedent = faultedCompletionSource.Task;
            object result = new object();
            Func<Task, object> continuationFunction = task =>
                {
                    executed = true;
                    return result;
                };

            bool supportsErrors = false;

            Task<object> combinedTask = null;

            try
            {
                combinedTask = CoreTaskExtensions.Select(antecedent, continuationFunction, supportsErrors);
                combinedTask.Wait();
                Assert.Fail("Expected an ArgumentException wrapped in an AggregateException");
            }
            catch (AggregateException ex)
            {
                Assert.IsNotNull(combinedTask, "Failed to create the combined task.");
                Assert.AreEqual(TaskStatus.Faulted, combinedTask.Status);
                Assert.AreEqual(1, ex.InnerExceptions.Count);
                Assert.AreSame(expectedException, ex.InnerExceptions[0]);
                Assert.IsFalse(executed);
            }
        }

        /// <summary>
        /// This method test the behavior of the
        /// <see cref="CoreTaskExtensions.Select{TResult}(Task, Func{Task, TResult}, bool)"/>
        /// method.
        /// </summary>
        [TestMethod]
        public void TestSelect4_CompletedAntecedent_FaultedContinuation_NoErrors()
        {
            bool executed = false;

            // declaring these makes it clear we are testing the correct overload
            Task antecedent = CompletedTask.Default;

            Exception continuationException = new InvalidOperationException();
            Func<Task, object> continuationFunction = task =>
                {
                    executed = true;
                    throw continuationException;
                };

            bool supportsErrors = false;

            Task<object> combinedTask = null;

            try
            {
                combinedTask = CoreTaskExtensions.Select(antecedent, continuationFunction, supportsErrors);
                combinedTask.Wait();
                Assert.Fail("Expected an InvalidOperationException wrapped in an AggregateException");
            }
            catch (AggregateException ex)
            {
                Assert.IsNotNull(combinedTask, "Failed to create the combined task.");
                Assert.AreEqual(TaskStatus.Faulted, combinedTask.Status);
                Assert.AreEqual(1, ex.InnerExceptions.Count);
                Assert.AreSame(continuationException, ex.InnerExceptions[0]);
                Assert.IsTrue(executed);
            }
        }

        /// <summary>
        /// This method test the behavior of the
        /// <see cref="CoreTaskExtensions.Select{TResult}(Task, Func{Task, TResult}, bool)"/>
        /// method.
        /// </summary>
        [TestMethod]
        public void TestSelect4_CanceledAntecedent_FaultedContinuation_NoErrors()
        {
            bool executed = false;

            // declaring these makes it clear we are testing the correct overload
            Task antecedent = CompletedTask.Canceled();

            Exception continuationException = new InvalidOperationException();
            Func<Task, object> continuationFunction = task =>
                {
                    executed = true;
                    throw continuationException;
                };

            bool supportsErrors = false;

            Task<object> combinedTask = null;

            try
            {
                combinedTask = CoreTaskExtensions.Select(antecedent, continuationFunction, supportsErrors);
                combinedTask.Wait();
                Assert.Fail("Expected a TaskCanceledException wrapped in an AggregateException");
            }
            catch (AggregateException ex)
            {
                Assert.IsNotNull(combinedTask, "Failed to create the combined task.");
                Assert.AreEqual(TaskStatus.Canceled, combinedTask.Status);
                Assert.AreEqual(1, ex.InnerExceptions.Count);
                Assert.IsInstanceOfType(ex.InnerExceptions[0], typeof(TaskCanceledException));
                Assert.IsFalse(executed);
            }
        }

        /// <summary>
        /// This method test the behavior of the
        /// <see cref="CoreTaskExtensions.Select{TResult}(Task, Func{Task, TResult}, bool)"/>
        /// method.
        /// </summary>
        [TestMethod]
        public void TestSelect4_FaultedAntecedent_FaultedContinuation_NoErrors()
        {
            bool executed = false;

            // declaring these makes it clear we are testing the correct overload
            TaskCompletionSource<object> faultedCompletionSource = new TaskCompletionSource<object>();
            Exception expectedException = new ArgumentException();
            faultedCompletionSource.SetException(expectedException);
            Task antecedent = faultedCompletionSource.Task;

            Exception continuationException = new InvalidOperationException();
            Func<Task, object> continuationFunction = task =>
                {
                    executed = true;
                    throw continuationException;
                };

            bool supportsErrors = false;

            Task<object> combinedTask = null;

            try
            {
                combinedTask = CoreTaskExtensions.Select(antecedent, continuationFunction, supportsErrors);
                combinedTask.Wait();
                Assert.Fail("Expected an ArgumentException wrapped in an AggregateException");
            }
            catch (AggregateException ex)
            {
                Assert.IsNotNull(combinedTask, "Failed to create the combined task.");
                Assert.AreEqual(TaskStatus.Faulted, combinedTask.Status);
                Assert.AreEqual(1, ex.InnerExceptions.Count);
                Assert.AreSame(expectedException, ex.InnerExceptions[0]);
                Assert.IsFalse(executed);
            }
        }

        /// <summary>
        /// This method test the behavior of the
        /// <see cref="CoreTaskExtensions.Select{TResult}(Task, Func{Task, TResult}, bool)"/>
        /// method.
        /// </summary>
        [TestMethod]
        [ExpectedException(typeof(ArgumentNullException))]
        public void TestSelect4_NullAntecedent_CompletedContinuation_SupportsErrors()
        {
            // declaring these makes it clear we are testing the correct overload
            Task antecedent = null;
            object result = new object();
            Func<Task, object> continuationFunction = task => result;

            bool supportsErrors = true;

            CoreTaskExtensions.Select(antecedent, continuationFunction, supportsErrors);
        }

        /// <summary>
        /// This method test the behavior of the
        /// <see cref="CoreTaskExtensions.Select{TResult}(Task, Func{Task, TResult}, bool)"/>
        /// method.
        /// </summary>
        [TestMethod]
        [ExpectedException(typeof(ArgumentNullException))]
        public void TestSelect4_CompletedAntecedent_NullContinuation_SupportsErrors()
        {
            // declaring these makes it clear we are testing the correct overload
            Task antecedent = CompletedTask.Default;
            Func<Task, object> continuationFunction = null;

            bool supportsErrors = true;

            CoreTaskExtensions.Select(antecedent, continuationFunction, supportsErrors);
        }

        /// <summary>
        /// This method test the behavior of the
        /// <see cref="CoreTaskExtensions.Select{TResult}(Task, Func{Task, TResult}, bool)"/>
        /// method.
        /// </summary>
        [TestMethod]
        public void TestSelect4_CompletedAntecedent_CompletedContinuation_SupportsErrors()
        {
            bool executed = false;

            // declaring these makes it clear we are testing the correct overload
            Task antecedent = CompletedTask.Default;
            object result = new object();
            Func<Task, object> continuationFunction = task =>
                {
                    executed = true;
                    return result;
                };

            bool supportsErrors = true;

            Task<object> combinedTask = CoreTaskExtensions.Select(antecedent, continuationFunction, supportsErrors);
            combinedTask.Wait();
            Assert.AreEqual(TaskStatus.RanToCompletion, combinedTask.Status);
            Assert.IsTrue(executed);
        }

        /// <summary>
        /// This method test the behavior of the
        /// <see cref="CoreTaskExtensions.Select{TResult}(Task, Func{Task, TResult}, bool)"/>
        /// method.
        /// </summary>
        [TestMethod]
        public void TestSelect4_CanceledAntecedent_CompletedContinuation_SupportsErrors()
        {
            bool executed = false;

            // declaring these makes it clear we are testing the correct overload
            Task antecedent = CompletedTask.Canceled();
            object result = new object();
            Func<Task, object> continuationFunction = task =>
                {
                    executed = true;
                    return result;
                };

            bool supportsErrors = true;

            Task<object> combinedTask = null;

            try
            {
                combinedTask = CoreTaskExtensions.Select(antecedent, continuationFunction, supportsErrors);
                combinedTask.Wait();
                Assert.Fail("Expected a TaskCanceledException wrapped in an AggregateException");
            }
            catch (AggregateException ex)
            {
                Assert.IsNotNull(combinedTask, "Failed to create the combined task.");
                Assert.AreEqual(TaskStatus.Canceled, combinedTask.Status);
                Assert.AreEqual(1, ex.InnerExceptions.Count);
                Assert.IsInstanceOfType(ex.InnerExceptions[0], typeof(TaskCanceledException));
                Assert.IsFalse(executed);
            }
        }

        /// <summary>
        /// This method test the behavior of the
        /// <see cref="CoreTaskExtensions.Select{TResult}(Task, Func{Task, TResult}, bool)"/>
        /// method.
        /// </summary>
        [TestMethod]
        public void TestSelect4_FaultedAntecedent_CompletedContinuation_SupportsErrors()
        {
            bool executed = false;

            // declaring these makes it clear we are testing the correct overload
            TaskCompletionSource<object> faultedCompletionSource = new TaskCompletionSource<object>();
            Exception expectedException = new ArgumentException();
            faultedCompletionSource.SetException(expectedException);
            Task antecedent = faultedCompletionSource.Task;
            object result = new object();
            Func<Task, object> continuationFunction = task =>
                {
                    executed = true;
                    return result;
                };

            bool supportsErrors = true;

            Task<object> combinedTask = CoreTaskExtensions.Select(antecedent, continuationFunction, supportsErrors);
            combinedTask.Wait();
            Assert.AreEqual(TaskStatus.RanToCompletion, combinedTask.Status);
            Assert.AreSame(result, combinedTask.Result);
            Assert.IsTrue(executed);
        }

        /// <summary>
        /// This method test the behavior of the
        /// <see cref="CoreTaskExtensions.Select{TResult}(Task, Func{Task, TResult}, bool)"/>
        /// method.
        /// </summary>
        [TestMethod]
        public void TestSelect4_CompletedAntecedent_FaultedContinuation_SupportsErrors()
        {
            bool executed = false;

            // declaring these makes it clear we are testing the correct overload
            Task antecedent = CompletedTask.Default;

            Exception continuationException = new InvalidOperationException();
            Func<Task, object> continuationFunction = task =>
                {
                    executed = true;
                    throw continuationException;
                };

            bool supportsErrors = true;

            Task<object> combinedTask = null;

            try
            {
                combinedTask = CoreTaskExtensions.Select(antecedent, continuationFunction, supportsErrors);
                combinedTask.Wait();
                Assert.Fail("Expected an InvalidOperationException wrapped in an AggregateException");
            }
            catch (AggregateException ex)
            {
                Assert.IsNotNull(combinedTask, "Failed to create the combined task.");
                Assert.AreEqual(TaskStatus.Faulted, combinedTask.Status);
                Assert.AreEqual(1, ex.InnerExceptions.Count);
                Assert.AreSame(continuationException, ex.InnerExceptions[0]);
                Assert.IsTrue(executed);
            }
        }

        /// <summary>
        /// This method test the behavior of the
        /// <see cref="CoreTaskExtensions.Select{TResult}(Task, Func{Task, TResult}, bool)"/>
        /// method.
        /// </summary>
        [TestMethod]
        public void TestSelect4_CanceledAntecedent_FaultedContinuation_SupportsErrors()
        {
            bool executed = false;

            // declaring these makes it clear we are testing the correct overload
            Task antecedent = CompletedTask.Canceled();

            Exception continuationException = new InvalidOperationException();
            Func<Task, object> continuationFunction = task =>
                {
                    executed = true;
                    throw continuationException;
                };

            bool supportsErrors = true;

            Task<object> combinedTask = null;

            try
            {
                combinedTask = CoreTaskExtensions.Select(antecedent, continuationFunction, supportsErrors);
                combinedTask.Wait();
                Assert.Fail("Expected a TaskCanceledException wrapped in an AggregateException");
            }
            catch (AggregateException ex)
            {
                Assert.IsNotNull(combinedTask, "Failed to create the combined task.");
                Assert.AreEqual(TaskStatus.Canceled, combinedTask.Status);
                Assert.AreEqual(1, ex.InnerExceptions.Count);
                Assert.IsInstanceOfType(ex.InnerExceptions[0], typeof(TaskCanceledException));
                Assert.IsFalse(executed);
            }
        }

        /// <summary>
        /// This method test the behavior of the
        /// <see cref="CoreTaskExtensions.Select{TResult}(Task, Func{Task, TResult}, bool)"/>
        /// method.
        /// </summary>
        [TestMethod]
        public void TestSelect4_FaultedAntecedent_FaultedContinuation_SupportsErrors()
        {
            bool executed = false;

            // declaring these makes it clear we are testing the correct overload
            TaskCompletionSource<object> faultedCompletionSource = new TaskCompletionSource<object>();
            Exception expectedException = new ArgumentException();
            faultedCompletionSource.SetException(expectedException);
            Task antecedent = faultedCompletionSource.Task;

            Exception continuationException = new InvalidOperationException();
            Func<Task, object> continuationFunction = task =>
                {
                    executed = true;
                    throw continuationException;
                };

            bool supportsErrors = true;

            Task<object> combinedTask = null;

            try
            {
                combinedTask = CoreTaskExtensions.Select(antecedent, continuationFunction, supportsErrors);
                combinedTask.Wait();
                Assert.Fail("Expected an InvalidOperationException wrapped in an AggregateException");
            }
            catch (AggregateException ex)
            {
                Assert.IsNotNull(combinedTask, "Failed to create the combined task.");
                Assert.AreEqual(TaskStatus.Faulted, combinedTask.Status);
                Assert.AreEqual(1, ex.InnerExceptions.Count);
                Assert.AreSame(continuationException, ex.InnerExceptions[0]);
                Assert.IsTrue(executed);
            }
        }

        #endregion

        #region Select 5

        /// <summary>
        /// This method test the behavior of the
        /// <see cref="CoreTaskExtensions.Select{TSource, TResult}(Task{TSource}, Func{Task{TSource}, TResult})"/>
        /// method.
        /// </summary>
        [TestMethod]
        [ExpectedException(typeof(ArgumentNullException))]
        public void TestSelect5_NullAntecedent_CompletedContinuation()
        {
            // declaring these makes it clear we are testing the correct overload
            Task<List<object>> antecedent = null;
            string result = "Test string";
            Func<Task<List<object>>, string> continuationFunction = task => result;

            CoreTaskExtensions.Select(antecedent, continuationFunction);
        }

        /// <summary>
        /// This method test the behavior of the
        /// <see cref="CoreTaskExtensions.Select{TSource, TResult}(Task{TSource}, Func{Task{TSource}, TResult})"/>
        /// method.
        /// </summary>
        [TestMethod]
        [ExpectedException(typeof(ArgumentNullException))]
        public void TestSelect5_CompletedAntecedent_NullContinuation()
        {
            // declaring these makes it clear we are testing the correct overload
            Task<List<object>> antecedent = CompletedTask.FromResult(new List<object>());
            Func<Task<List<object>>, string> continuationFunction = null;

            CoreTaskExtensions.Select(antecedent, continuationFunction);
        }

        /// <summary>
        /// This method test the behavior of the
        /// <see cref="CoreTaskExtensions.Select{TSource, TResult}(Task{TSource}, Func{Task{TSource}, TResult})"/>
        /// method.
        /// </summary>
        [TestMethod]
        public void TestSelect5_CompletedAntecedent_CompletedContinuation()
        {
            bool executed = false;

            // declaring these makes it clear we are testing the correct overload
            Task<List<object>> antecedent = CompletedTask.FromResult(new List<object>());
            string result = "Test string";
            Func<Task<List<object>>, string> continuationFunction = task =>
                {
                    executed = true;
                    return result;
                };

            Task<string> combinedTask = CoreTaskExtensions.Select(antecedent, continuationFunction);
            combinedTask.Wait();
            Assert.AreEqual(TaskStatus.RanToCompletion, combinedTask.Status);
            Assert.AreSame(result, combinedTask.Result);
            Assert.IsTrue(executed);
        }

        /// <summary>
        /// This method test the behavior of the
        /// <see cref="CoreTaskExtensions.Select{TSource, TResult}(Task{TSource}, Func{Task{TSource}, TResult})"/>
        /// method.
        /// </summary>
        [TestMethod]
        public void TestSelect5_CanceledAntecedent_CompletedContinuation()
        {
            bool executed = false;

            // declaring these makes it clear we are testing the correct overload
            Task<List<object>> antecedent = CompletedTask.Canceled<List<object>>();
            string result = "Test string";
            Func<Task<List<object>>, string> continuationFunction = task =>
                {
                    executed = true;
                    return result;
                };

            Task<string> combinedTask = null;

            try
            {
                combinedTask = CoreTaskExtensions.Select(antecedent, continuationFunction);
                combinedTask.Wait();
                Assert.Fail("Expected a TaskCanceledException wrapped in an AggregateException");
            }
            catch (AggregateException ex)
            {
                Assert.IsNotNull(combinedTask, "Failed to create the combined task.");
                Assert.AreEqual(TaskStatus.Canceled, combinedTask.Status);
                Assert.AreEqual(1, ex.InnerExceptions.Count);
                Assert.IsInstanceOfType(ex.InnerExceptions[0], typeof(TaskCanceledException));
                Assert.IsFalse(executed);
            }
        }

        /// <summary>
        /// This method test the behavior of the
        /// <see cref="CoreTaskExtensions.Select{TSource, TResult}(Task{TSource}, Func{Task{TSource}, TResult})"/>
        /// method.
        /// </summary>
        [TestMethod]
        public void TestSelect5_FaultedAntecedent_CompletedContinuation()
        {
            bool executed = false;

            // declaring these makes it clear we are testing the correct overload
            TaskCompletionSource<List<object>> faultedCompletionSource = new TaskCompletionSource<List<object>>();
            Exception expectedException = new ArgumentException();
            faultedCompletionSource.SetException(expectedException);
            Task<List<object>> antecedent = faultedCompletionSource.Task;
            string result = "Test string";
            Func<Task<List<object>>, string> continuationFunction = task =>
                {
                    executed = true;
                    return result;
                };

            Task<string> combinedTask = null;

            try
            {
                combinedTask = CoreTaskExtensions.Select(antecedent, continuationFunction);
                combinedTask.Wait();
                Assert.Fail("Expected an ArgumentException wrapped in an AggregateException");
            }
            catch (AggregateException ex)
            {
                Assert.IsNotNull(combinedTask, "Failed to create the combined task.");
                Assert.AreEqual(TaskStatus.Faulted, combinedTask.Status);
                Assert.AreEqual(1, ex.InnerExceptions.Count);
                Assert.AreSame(expectedException, ex.InnerExceptions[0]);
                Assert.IsFalse(executed);
            }
        }

        /// <summary>
        /// This method test the behavior of the
        /// <see cref="CoreTaskExtensions.Select{TSource, TResult}(Task{TSource}, Func{Task{TSource}, TResult})"/>
        /// method.
        /// </summary>
        [TestMethod]
        public void TestSelect5_CompletedAntecedent_FaultedContinuation()
        {
            bool executed = false;

            // declaring these makes it clear we are testing the correct overload
            Task<List<object>> antecedent = CompletedTask.FromResult(new List<object>());

            Exception continuationException = new InvalidOperationException();
            Func<Task<List<object>>, string> continuationFunction = task =>
                {
                    executed = true;
                    throw continuationException;
                };

            Task<string> combinedTask = null;

            try
            {
                combinedTask = CoreTaskExtensions.Select(antecedent, continuationFunction);
                combinedTask.Wait();
                Assert.Fail("Expected an InvalidOperationException wrapped in an AggregateException");
            }
            catch (AggregateException ex)
            {
                Assert.IsNotNull(combinedTask, "Failed to create the combined task.");
                Assert.AreEqual(TaskStatus.Faulted, combinedTask.Status);
                Assert.AreEqual(1, ex.InnerExceptions.Count);
                Assert.AreSame(continuationException, ex.InnerExceptions[0]);
                Assert.IsTrue(executed);
            }
        }

        /// <summary>
        /// This method test the behavior of the
        /// <see cref="CoreTaskExtensions.Select{TSource, TResult}(Task{TSource}, Func{Task{TSource}, TResult})"/>
        /// method.
        /// </summary>
        [TestMethod]
        public void TestSelect5_CanceledAntecedent_FaultedContinuation()
        {
            bool executed = false;

            // declaring these makes it clear we are testing the correct overload
            Task<List<object>> antecedent = CompletedTask.Canceled<List<object>>();

            Exception continuationException = new InvalidOperationException();
            Func<Task<List<object>>, string> continuationFunction = task =>
                {
                    executed = true;
                    throw continuationException;
                };

            Task<string> combinedTask = null;

            try
            {
                combinedTask = CoreTaskExtensions.Select(antecedent, continuationFunction);
                combinedTask.Wait();
                Assert.Fail("Expected a TaskCanceledException wrapped in an AggregateException");
            }
            catch (AggregateException ex)
            {
                Assert.IsNotNull(combinedTask, "Failed to create the combined task.");
                Assert.AreEqual(TaskStatus.Canceled, combinedTask.Status);
                Assert.AreEqual(1, ex.InnerExceptions.Count);
                Assert.IsInstanceOfType(ex.InnerExceptions[0], typeof(TaskCanceledException));
                Assert.IsFalse(executed);
            }
        }

        /// <summary>
        /// This method test the behavior of the
        /// <see cref="CoreTaskExtensions.Select{TSource, TResult}(Task{TSource}, Func{Task{TSource}, TResult})"/>
        /// method.
        /// </summary>
        [TestMethod]
        public void TestSelect5_FaultedAntecedent_FaultedContinuation()
        {
            bool executed = false;

            // declaring these makes it clear we are testing the correct overload
            TaskCompletionSource<List<object>> faultedCompletionSource = new TaskCompletionSource<List<object>>();
            Exception expectedException = new ArgumentException();
            faultedCompletionSource.SetException(expectedException);
            Task<List<object>> antecedent = faultedCompletionSource.Task;

            Exception continuationException = new InvalidOperationException();
            Func<Task<List<object>>, string> continuationFunction = task =>
                {
                    executed = true;
                    throw continuationException;
                };

            Task<string> combinedTask = null;

            try
            {
                combinedTask = CoreTaskExtensions.Select(antecedent, continuationFunction);
                combinedTask.Wait();
                Assert.Fail("Expected an ArgumentException wrapped in an AggregateException");
            }
            catch (AggregateException ex)
            {
                Assert.IsNotNull(combinedTask, "Failed to create the combined task.");
                Assert.AreEqual(TaskStatus.Faulted, combinedTask.Status);
                Assert.AreEqual(1, ex.InnerExceptions.Count);
                Assert.AreSame(expectedException, ex.InnerExceptions[0]);
                Assert.IsFalse(executed);
            }
        }

        #endregion

        #region Select 6

        /// <summary>
        /// This method test the behavior of the
        /// <see cref="CoreTaskExtensions.Select{TSource, TResult}(Task{TSource}, Func{Task{TSource}, TResult}, bool)"/>
        /// method.
        /// </summary>
        [TestMethod]
        [ExpectedException(typeof(ArgumentNullException))]
        public void TestSelect6_NullAntecedent_CompletedContinuation_NoErrors()
        {
            // declaring these makes it clear we are testing the correct overload
            Task<List<object>> antecedent = null;
            string result = "Test string";
            Func<Task<List<object>>, string> continuationFunction = task => result;

            bool supportsErrors = false;

            CoreTaskExtensions.Select(antecedent, continuationFunction, supportsErrors);
        }

        /// <summary>
        /// This method test the behavior of the
        /// <see cref="CoreTaskExtensions.Select{TSource, TResult}(Task{TSource}, Func{Task{TSource}, TResult}, bool)"/>
        /// method.
        /// </summary>
        [TestMethod]
        [ExpectedException(typeof(ArgumentNullException))]
        public void TestSelect6_CompletedAntecedent_NullContinuation_NoErrors()
        {
            // declaring these makes it clear we are testing the correct overload
            Task<List<object>> antecedent = CompletedTask.FromResult(new List<object>());
            Func<Task<List<object>>, string> continuationFunction = null;

            bool supportsErrors = false;

            CoreTaskExtensions.Select(antecedent, continuationFunction, supportsErrors);
        }

        /// <summary>
        /// This method test the behavior of the
        /// <see cref="CoreTaskExtensions.Select{TSource, TResult}(Task{TSource}, Func{Task{TSource}, TResult}, bool)"/>
        /// method.
        /// </summary>
        [TestMethod]
        public void TestSelect6_CompletedAntecedent_CompletedContinuation_NoErrors()
        {
            bool executed = false;

            // declaring these makes it clear we are testing the correct overload
            Task<List<object>> antecedent = CompletedTask.FromResult(new List<object>());
            string result = "Test string";
            Func<Task<List<object>>, string> continuationFunction = task =>
                {
                    executed = true;
                    return result;
                };

            bool supportsErrors = false;

            Task<string> combinedTask = CoreTaskExtensions.Select(antecedent, continuationFunction, supportsErrors);
            combinedTask.Wait();
            Assert.AreEqual(TaskStatus.RanToCompletion, combinedTask.Status);
            Assert.AreSame(result, combinedTask.Result);
            Assert.IsTrue(executed);
        }

        /// <summary>
        /// This method test the behavior of the
        /// <see cref="CoreTaskExtensions.Select{TSource, TResult}(Task{TSource}, Func{Task{TSource}, TResult}, bool)"/>
        /// method.
        /// </summary>
        [TestMethod]
        public void TestSelect6_CanceledAntecedent_CompletedContinuation_NoErrors()
        {
            bool executed = false;

            // declaring these makes it clear we are testing the correct overload
            Task<List<object>> antecedent = CompletedTask.Canceled<List<object>>();
            string result = "Test string";
            Func<Task<List<object>>, string> continuationFunction = task =>
                {
                    executed = true;
                    return result;
                };

            bool supportsErrors = false;

            Task<string> combinedTask = null;

            try
            {
                combinedTask = CoreTaskExtensions.Select(antecedent, continuationFunction, supportsErrors);
                combinedTask.Wait();
                Assert.Fail("Expected a TaskCanceledException wrapped in an AggregateException");
            }
            catch (AggregateException ex)
            {
                Assert.IsNotNull(combinedTask, "Failed to create the combined task.");
                Assert.AreEqual(TaskStatus.Canceled, combinedTask.Status);
                Assert.AreEqual(1, ex.InnerExceptions.Count);
                Assert.IsInstanceOfType(ex.InnerExceptions[0], typeof(TaskCanceledException));
                Assert.IsFalse(executed);
            }
        }

        /// <summary>
        /// This method test the behavior of the
        /// <see cref="CoreTaskExtensions.Select{TSource, TResult}(Task{TSource}, Func{Task{TSource}, TResult}, bool)"/>
        /// method.
        /// </summary>
        [TestMethod]
        public void TestSelect6_FaultedAntecedent_CompletedContinuation_NoErrors()
        {
            bool executed = false;

            // declaring these makes it clear we are testing the correct overload
            TaskCompletionSource<List<object>> faultedCompletionSource = new TaskCompletionSource<List<object>>();
            Exception expectedException = new ArgumentException();
            faultedCompletionSource.SetException(expectedException);
            Task<List<object>> antecedent = faultedCompletionSource.Task;
            string result = "Test string";
            Func<Task<List<object>>, string> continuationFunction = task =>
                {
                    executed = true;
                    return result;
                };

            bool supportsErrors = false;

            Task<string> combinedTask = null;

            try
            {
                combinedTask = CoreTaskExtensions.Select(antecedent, continuationFunction, supportsErrors);
                combinedTask.Wait();
                Assert.Fail("Expected an ArgumentException wrapped in an AggregateException");
            }
            catch (AggregateException ex)
            {
                Assert.IsNotNull(combinedTask, "Failed to create the combined task.");
                Assert.AreEqual(TaskStatus.Faulted, combinedTask.Status);
                Assert.AreEqual(1, ex.InnerExceptions.Count);
                Assert.AreSame(expectedException, ex.InnerExceptions[0]);
                Assert.IsFalse(executed);
            }
        }

        /// <summary>
        /// This method test the behavior of the
        /// <see cref="CoreTaskExtensions.Select{TSource, TResult}(Task{TSource}, Func{Task{TSource}, TResult}, bool)"/>
        /// method.
        /// </summary>
        [TestMethod]
        public void TestSelect6_CompletedAntecedent_FaultedContinuation_NoErrors()
        {
            bool executed = false;

            // declaring these makes it clear we are testing the correct overload
            Task<List<object>> antecedent = CompletedTask.FromResult(new List<object>());

            Exception continuationException = new InvalidOperationException();
            Func<Task<List<object>>, string> continuationFunction = task =>
                {
                    executed = true;
                    throw continuationException;
                };

            bool supportsErrors = false;

            Task<string> combinedTask = null;

            try
            {
                combinedTask = CoreTaskExtensions.Select(antecedent, continuationFunction, supportsErrors);
                combinedTask.Wait();
                Assert.Fail("Expected an InvalidOperationException wrapped in an AggregateException");
            }
            catch (AggregateException ex)
            {
                Assert.IsNotNull(combinedTask, "Failed to create the combined task.");
                Assert.AreEqual(TaskStatus.Faulted, combinedTask.Status);
                Assert.AreEqual(1, ex.InnerExceptions.Count);
                Assert.AreSame(continuationException, ex.InnerExceptions[0]);
                Assert.IsTrue(executed);
            }
        }

        /// <summary>
        /// This method test the behavior of the
        /// <see cref="CoreTaskExtensions.Select{TSource, TResult}(Task{TSource}, Func{Task{TSource}, TResult}, bool)"/>
        /// method.
        /// </summary>
        [TestMethod]
        public void TestSelect6_CanceledAntecedent_FaultedContinuation_NoErrors()
        {
            bool executed = false;

            // declaring these makes it clear we are testing the correct overload
            Task<List<object>> antecedent = CompletedTask.Canceled<List<object>>();

            Exception continuationException = new InvalidOperationException();
            Func<Task<List<object>>, string> continuationFunction = task =>
                {
                    executed = true;
                    throw continuationException;
                };

            bool supportsErrors = false;

            Task<string> combinedTask = null;

            try
            {
                combinedTask = CoreTaskExtensions.Select(antecedent, continuationFunction, supportsErrors);
                combinedTask.Wait();
                Assert.Fail("Expected a TaskCanceledException wrapped in an AggregateException");
            }
            catch (AggregateException ex)
            {
                Assert.IsNotNull(combinedTask, "Failed to create the combined task.");
                Assert.AreEqual(TaskStatus.Canceled, combinedTask.Status);
                Assert.AreEqual(1, ex.InnerExceptions.Count);
                Assert.IsInstanceOfType(ex.InnerExceptions[0], typeof(TaskCanceledException));
                Assert.IsFalse(executed);
            }
        }

        /// <summary>
        /// This method test the behavior of the
        /// <see cref="CoreTaskExtensions.Select{TSource, TResult}(Task{TSource}, Func{Task{TSource}, TResult}, bool)"/>
        /// method.
        /// </summary>
        [TestMethod]
        public void TestSelect6_FaultedAntecedent_FaultedContinuation_NoErrors()
        {
            bool executed = false;

            // declaring these makes it clear we are testing the correct overload
            TaskCompletionSource<List<object>> faultedCompletionSource = new TaskCompletionSource<List<object>>();
            Exception expectedException = new ArgumentException();
            faultedCompletionSource.SetException(expectedException);
            Task<List<object>> antecedent = faultedCompletionSource.Task;

            Exception continuationException = new InvalidOperationException();
            Func<Task<List<object>>, string> continuationFunction = task =>
                {
                    executed = true;
                    throw continuationException;
                };

            bool supportsErrors = false;

            Task<string> combinedTask = null;

            try
            {
                combinedTask = CoreTaskExtensions.Select(antecedent, continuationFunction, supportsErrors);
                combinedTask.Wait();
                Assert.Fail("Expected an ArgumentException wrapped in an AggregateException");
            }
            catch (AggregateException ex)
            {
                Assert.IsNotNull(combinedTask, "Failed to create the combined task.");
                Assert.AreEqual(TaskStatus.Faulted, combinedTask.Status);
                Assert.AreEqual(1, ex.InnerExceptions.Count);
                Assert.AreSame(expectedException, ex.InnerExceptions[0]);
                Assert.IsFalse(executed);
            }
        }

        /// <summary>
        /// This method test the behavior of the
        /// <see cref="CoreTaskExtensions.Select{TSource, TResult}(Task{TSource}, Func{Task{TSource}, TResult}, bool)"/>
        /// method.
        /// </summary>
        [TestMethod]
        [ExpectedException(typeof(ArgumentNullException))]
        public void TestSelect6_NullAntecedent_CompletedContinuation_SupportsErrors()
        {
            // declaring these makes it clear we are testing the correct overload
            Task<List<object>> antecedent = null;
            string result = "Test string";
            Func<Task<List<object>>, string> continuationFunction = task => result;

            bool supportsErrors = true;

            CoreTaskExtensions.Select(antecedent, continuationFunction, supportsErrors);
        }

        /// <summary>
        /// This method test the behavior of the
        /// <see cref="CoreTaskExtensions.Select{TSource, TResult}(Task{TSource}, Func{Task{TSource}, TResult}, bool)"/>
        /// method.
        /// </summary>
        [TestMethod]
        [ExpectedException(typeof(ArgumentNullException))]
        public void TestSelect6_CompletedAntecedent_NullContinuation_SupportsErrors()
        {
            // declaring these makes it clear we are testing the correct overload
            Task<List<object>> antecedent = CompletedTask.FromResult(new List<object>());
            Func<Task<List<object>>, string> continuationFunction = null;

            bool supportsErrors = true;

            CoreTaskExtensions.Select(antecedent, continuationFunction, supportsErrors);
        }

        /// <summary>
        /// This method test the behavior of the
        /// <see cref="CoreTaskExtensions.Select{TSource, TResult}(Task{TSource}, Func{Task{TSource}, TResult}, bool)"/>
        /// method.
        /// </summary>
        [TestMethod]
        public void TestSelect6_CompletedAntecedent_CompletedContinuation_SupportsErrors()
        {
            bool executed = false;

            // declaring these makes it clear we are testing the correct overload
            Task<List<object>> antecedent = CompletedTask.FromResult(new List<object>());
            string result = "Test string";
            Func<Task<List<object>>, string> continuationFunction = task =>
                {
                    executed = true;
                    return result;
                };

            bool supportsErrors = true;

            Task<string> combinedTask = CoreTaskExtensions.Select(antecedent, continuationFunction, supportsErrors);
            combinedTask.Wait();
            Assert.AreEqual(TaskStatus.RanToCompletion, combinedTask.Status);
            Assert.IsTrue(executed);
        }

        /// <summary>
        /// This method test the behavior of the
        /// <see cref="CoreTaskExtensions.Select{TSource, TResult}(Task{TSource}, Func{Task{TSource}, TResult}, bool)"/>
        /// method.
        /// </summary>
        [TestMethod]
        public void TestSelect6_CanceledAntecedent_CompletedContinuation_SupportsErrors()
        {
            bool executed = false;

            // declaring these makes it clear we are testing the correct overload
            Task<List<object>> antecedent = CompletedTask.Canceled<List<object>>();
            string result = "Test string";
            Func<Task<List<object>>, string> continuationFunction = task =>
                {
                    executed = true;
                    return result;
                };

            bool supportsErrors = true;

            Task<string> combinedTask = null;

            try
            {
                combinedTask = CoreTaskExtensions.Select(antecedent, continuationFunction, supportsErrors);
                combinedTask.Wait();
                Assert.Fail("Expected a TaskCanceledException wrapped in an AggregateException");
            }
            catch (AggregateException ex)
            {
                Assert.IsNotNull(combinedTask, "Failed to create the combined task.");
                Assert.AreEqual(TaskStatus.Canceled, combinedTask.Status);
                Assert.AreEqual(1, ex.InnerExceptions.Count);
                Assert.IsInstanceOfType(ex.InnerExceptions[0], typeof(TaskCanceledException));
                Assert.IsFalse(executed);
            }
        }

        /// <summary>
        /// This method test the behavior of the
        /// <see cref="CoreTaskExtensions.Select{TSource, TResult}(Task{TSource}, Func{Task{TSource}, TResult}, bool)"/>
        /// method.
        /// </summary>
        [TestMethod]
        public void TestSelect6_FaultedAntecedent_CompletedContinuation_SupportsErrors()
        {
            bool executed = false;

            // declaring these makes it clear we are testing the correct overload
            TaskCompletionSource<List<object>> faultedCompletionSource = new TaskCompletionSource<List<object>>();
            Exception expectedException = new ArgumentException();
            faultedCompletionSource.SetException(expectedException);
            Task<List<object>> antecedent = faultedCompletionSource.Task;
            string result = "Test string";
            Func<Task<List<object>>, string> continuationFunction = task =>
                {
                    executed = true;
                    return result;
                };

            bool supportsErrors = true;

            Task<string> combinedTask = CoreTaskExtensions.Select(antecedent, continuationFunction, supportsErrors);
            combinedTask.Wait();
            Assert.AreEqual(TaskStatus.RanToCompletion, combinedTask.Status);
            Assert.AreSame(result, combinedTask.Result);
            Assert.IsTrue(executed);
        }

        /// <summary>
        /// This method test the behavior of the
        /// <see cref="CoreTaskExtensions.Select{TSource, TResult}(Task{TSource}, Func{Task{TSource}, TResult}, bool)"/>
        /// method.
        /// </summary>
        [TestMethod]
        public void TestSelect6_CompletedAntecedent_FaultedContinuation_SupportsErrors()
        {
            bool executed = false;

            // declaring these makes it clear we are testing the correct overload
            Task<List<object>> antecedent = CompletedTask.FromResult(new List<object>());

            Exception continuationException = new InvalidOperationException();
            Func<Task<List<object>>, string> continuationFunction = task =>
                {
                    executed = true;
                    throw continuationException;
                };

            bool supportsErrors = true;

            Task<string> combinedTask = null;

            try
            {
                combinedTask = CoreTaskExtensions.Select(antecedent, continuationFunction, supportsErrors);
                combinedTask.Wait();
                Assert.Fail("Expected an InvalidOperationException wrapped in an AggregateException");
            }
            catch (AggregateException ex)
            {
                Assert.IsNotNull(combinedTask, "Failed to create the combined task.");
                Assert.AreEqual(TaskStatus.Faulted, combinedTask.Status);
                Assert.AreEqual(1, ex.InnerExceptions.Count);
                Assert.AreSame(continuationException, ex.InnerExceptions[0]);
                Assert.IsTrue(executed);
            }
        }

        /// <summary>
        /// This method test the behavior of the
        /// <see cref="CoreTaskExtensions.Select{TSource, TResult}(Task{TSource}, Func{Task{TSource}, TResult}, bool)"/>
        /// method.
        /// </summary>
        [TestMethod]
        public void TestSelect6_CanceledAntecedent_FaultedContinuation_SupportsErrors()
        {
            bool executed = false;

            // declaring these makes it clear we are testing the correct overload
            Task<List<object>> antecedent = CompletedTask.Canceled<List<object>>();

            Exception continuationException = new InvalidOperationException();
            Func<Task<List<object>>, string> continuationFunction = task =>
                {
                    executed = true;
                    throw continuationException;
                };

            bool supportsErrors = true;

            Task<string> combinedTask = null;

            try
            {
                combinedTask = CoreTaskExtensions.Select(antecedent, continuationFunction, supportsErrors);
                combinedTask.Wait();
                Assert.Fail("Expected a TaskCanceledException wrapped in an AggregateException");
            }
            catch (AggregateException ex)
            {
                Assert.IsNotNull(combinedTask, "Failed to create the combined task.");
                Assert.AreEqual(TaskStatus.Canceled, combinedTask.Status);
                Assert.AreEqual(1, ex.InnerExceptions.Count);
                Assert.IsInstanceOfType(ex.InnerExceptions[0], typeof(TaskCanceledException));
                Assert.IsFalse(executed);
            }
        }

        /// <summary>
        /// This method test the behavior of the
        /// <see cref="CoreTaskExtensions.Select{TSource, TResult}(Task{TSource}, Func{Task{TSource}, TResult}, bool)"/>
        /// method.
        /// </summary>
        [TestMethod]
        public void TestSelect6_FaultedAntecedent_FaultedContinuation_SupportsErrors()
        {
            bool executed = false;

            // declaring these makes it clear we are testing the correct overload
            TaskCompletionSource<List<object>> faultedCompletionSource = new TaskCompletionSource<List<object>>();
            Exception expectedException = new ArgumentException();
            faultedCompletionSource.SetException(expectedException);
            Task<List<object>> antecedent = faultedCompletionSource.Task;

            Exception continuationException = new InvalidOperationException();
            Func<Task<List<object>>, string> continuationFunction = task =>
                {
                    executed = true;
                    throw continuationException;
                };

            bool supportsErrors = true;

            Task<string> combinedTask = null;

            try
            {
                combinedTask = CoreTaskExtensions.Select(antecedent, continuationFunction, supportsErrors);
                combinedTask.Wait();
                Assert.Fail("Expected an InvalidOperationException wrapped in an AggregateException");
            }
            catch (AggregateException ex)
            {
                Assert.IsNotNull(combinedTask, "Failed to create the combined task.");
                Assert.AreEqual(TaskStatus.Faulted, combinedTask.Status);
                Assert.AreEqual(1, ex.InnerExceptions.Count);
                Assert.AreSame(continuationException, ex.InnerExceptions[0]);
                Assert.IsTrue(executed);
            }
        }

        #endregion

        #region Select 7

        /// <summary>
        /// This method test the behavior of the
        /// <see cref="CoreTaskExtensions.Select{TSource}(Task{TSource}, Action{Task{TSource}})"/>
        /// method.
        /// </summary>
        [TestMethod]
        [ExpectedException(typeof(ArgumentNullException))]
        public void TestSelect7_NullAntecedent_CompletedContinuation()
        {
            // declaring these makes it clear we are testing the correct overload
            Task<string> antecedent = null;
            Action<Task<string>> continuationAction = task =>
                {
                };

            CoreTaskExtensions.Select(antecedent, continuationAction);
        }

        /// <summary>
        /// This method test the behavior of the
        /// <see cref="CoreTaskExtensions.Select{TSource}(Task{TSource}, Action{Task{TSource}})"/>
        /// method.
        /// </summary>
        [TestMethod]
        [ExpectedException(typeof(ArgumentNullException))]
        public void TestSelect7_CompletedAntecedent_NullContinuation()
        {
            // declaring these makes it clear we are testing the correct overload
            Task<string> antecedent = CompletedTask.FromResult("Test string");
            Action<Task<string>> continuationAction = null;

            CoreTaskExtensions.Select(antecedent, continuationAction);
        }

        /// <summary>
        /// This method test the behavior of the
        /// <see cref="CoreTaskExtensions.Select{TSource}(Task{TSource}, Action{Task{TSource}})"/>
        /// method.
        /// </summary>
        [TestMethod]
        public void TestSelect7_CompletedAntecedent_CompletedContinuation()
        {
            bool executed = false;

            // declaring these makes it clear we are testing the correct overload
            Task<string> antecedent = CompletedTask.FromResult("Test string");
            Action<Task<string>> continuationAction = task => executed = true;

            Task combinedTask = CoreTaskExtensions.Select(antecedent, continuationAction);
            combinedTask.Wait();
            Assert.AreEqual(TaskStatus.RanToCompletion, combinedTask.Status);
            Assert.IsTrue(executed);
        }

        /// <summary>
        /// This method test the behavior of the
        /// <see cref="CoreTaskExtensions.Select{TSource}(Task{TSource}, Action{Task{TSource}})"/>
        /// method.
        /// </summary>
        [TestMethod]
        public void TestSelect7_CanceledAntecedent_CompletedContinuation()
        {
            bool executed = false;

            // declaring these makes it clear we are testing the correct overload
            Task<string> antecedent = CompletedTask.Canceled<string>();
            Action<Task<string>> continuationAction = task => executed = true;

            Task combinedTask = null;

            try
            {
                combinedTask = CoreTaskExtensions.Select(antecedent, continuationAction);
                combinedTask.Wait();
                Assert.Fail("Expected a TaskCanceledException wrapped in an AggregateException");
            }
            catch (AggregateException ex)
            {
                Assert.IsNotNull(combinedTask, "Failed to create the combined task.");
                Assert.AreEqual(TaskStatus.Canceled, combinedTask.Status);
                Assert.AreEqual(1, ex.InnerExceptions.Count);
                Assert.IsInstanceOfType(ex.InnerExceptions[0], typeof(TaskCanceledException));
                Assert.IsFalse(executed);
            }
        }

        /// <summary>
        /// This method test the behavior of the
        /// <see cref="CoreTaskExtensions.Select{TSource}(Task{TSource}, Action{Task{TSource}})"/>
        /// method.
        /// </summary>
        [TestMethod]
        public void TestSelect7_FaultedAntecedent_CompletedContinuation()
        {
            bool executed = false;

            // declaring these makes it clear we are testing the correct overload
            TaskCompletionSource<string> faultedCompletionSource = new TaskCompletionSource<string>();
            Exception expectedException = new ArgumentException();
            faultedCompletionSource.SetException(expectedException);
            Task<string> antecedent = faultedCompletionSource.Task;
            Action<Task<string>> continuationAction = task => executed = true;

            Task combinedTask = null;

            try
            {
                combinedTask = CoreTaskExtensions.Select(antecedent, continuationAction);
                combinedTask.Wait();
                Assert.Fail("Expected an ArgumentException wrapped in an AggregateException");
            }
            catch (AggregateException ex)
            {
                Assert.IsNotNull(combinedTask, "Failed to create the combined task.");
                Assert.AreEqual(TaskStatus.Faulted, combinedTask.Status);
                Assert.AreEqual(1, ex.InnerExceptions.Count);
                Assert.AreSame(expectedException, ex.InnerExceptions[0]);
                Assert.IsFalse(executed);
            }
        }

        /// <summary>
        /// This method test the behavior of the
        /// <see cref="CoreTaskExtensions.Select{TSource}(Task{TSource}, Action{Task{TSource}})"/>
        /// method.
        /// </summary>
        [TestMethod]
        public void TestSelect7_CompletedAntecedent_FaultedContinuation()
        {
            bool executed = false;

            // declaring these makes it clear we are testing the correct overload
            Task<string> antecedent = CompletedTask.FromResult("Test string");

            Exception continuationException = new InvalidOperationException();
            Action<Task<string>> continuationAction = task =>
                {
                    executed = true;
                    throw continuationException;
                };

            Task combinedTask = null;

            try
            {
                combinedTask = CoreTaskExtensions.Select(antecedent, continuationAction);
                combinedTask.Wait();
                Assert.Fail("Expected an InvalidOperationException wrapped in an AggregateException");
            }
            catch (AggregateException ex)
            {
                Assert.IsNotNull(combinedTask, "Failed to create the combined task.");
                Assert.AreEqual(TaskStatus.Faulted, combinedTask.Status);
                Assert.AreEqual(1, ex.InnerExceptions.Count);
                Assert.AreSame(continuationException, ex.InnerExceptions[0]);
                Assert.IsTrue(executed);
            }
        }

        /// <summary>
        /// This method test the behavior of the
        /// <see cref="CoreTaskExtensions.Select{TSource}(Task{TSource}, Action{Task{TSource}})"/>
        /// method.
        /// </summary>
        [TestMethod]
        public void TestSelect7_CanceledAntecedent_FaultedContinuation()
        {
            bool executed = false;

            // declaring these makes it clear we are testing the correct overload
            Task<string> antecedent = CompletedTask.Canceled<string>();

            Exception continuationException = new InvalidOperationException();
            Action<Task<string>> continuationAction = task =>
                {
                    executed = true;
                    throw continuationException;
                };

            Task combinedTask = null;

            try
            {
                combinedTask = CoreTaskExtensions.Select(antecedent, continuationAction);
                combinedTask.Wait();
                Assert.Fail("Expected a TaskCanceledException wrapped in an AggregateException");
            }
            catch (AggregateException ex)
            {
                Assert.IsNotNull(combinedTask, "Failed to create the combined task.");
                Assert.AreEqual(TaskStatus.Canceled, combinedTask.Status);
                Assert.AreEqual(1, ex.InnerExceptions.Count);
                Assert.IsInstanceOfType(ex.InnerExceptions[0], typeof(TaskCanceledException));
                Assert.IsFalse(executed);
            }
        }

        /// <summary>
        /// This method test the behavior of the
        /// <see cref="CoreTaskExtensions.Select{TSource}(Task{TSource}, Action{Task{TSource}})"/>
        /// method.
        /// </summary>
        [TestMethod]
        public void TestSelect7_FaultedAntecedent_FaultedContinuation()
        {
            bool executed = false;

            // declaring these makes it clear we are testing the correct overload
            TaskCompletionSource<string> faultedCompletionSource = new TaskCompletionSource<string>();
            Exception expectedException = new ArgumentException();
            faultedCompletionSource.SetException(expectedException);
            Task<string> antecedent = faultedCompletionSource.Task;

            Exception continuationException = new InvalidOperationException();
            Action<Task<string>> continuationAction = task =>
                {
                    executed = true;
                    throw continuationException;
                };

            Task combinedTask = null;

            try
            {
                combinedTask = CoreTaskExtensions.Select(antecedent, continuationAction);
                combinedTask.Wait();
                Assert.Fail("Expected an ArgumentException wrapped in an AggregateException");
            }
            catch (AggregateException ex)
            {
                Assert.IsNotNull(combinedTask, "Failed to create the combined task.");
                Assert.AreEqual(TaskStatus.Faulted, combinedTask.Status);
                Assert.AreEqual(1, ex.InnerExceptions.Count);
                Assert.AreSame(expectedException, ex.InnerExceptions[0]);
                Assert.IsFalse(executed);
            }
        }

        #endregion

        #region Select 8

        /// <summary>
        /// This method test the behavior of the
        /// <see cref="CoreTaskExtensions.Select{TSource}(Task{TSource}, Action{Task{TSource}}, bool)"/>
        /// method.
        /// </summary>
        [TestMethod]
        [ExpectedException(typeof(ArgumentNullException))]
        public void TestSelect8_NullAntecedent_CompletedContinuation_NoErrors()
        {
            // declaring these makes it clear we are testing the correct overload
            Task<string> antecedent = null;
            Action<Task<string>> continuationAction = task =>
                {
                };
            bool supportsErrors = false;

            CoreTaskExtensions.Select(antecedent, continuationAction, supportsErrors);
        }

        /// <summary>
        /// This method test the behavior of the
        /// <see cref="CoreTaskExtensions.Select{TSource}(Task{TSource}, Action{Task{TSource}}, bool)"/>
        /// method.
        /// </summary>
        [TestMethod]
        [ExpectedException(typeof(ArgumentNullException))]
        public void TestSelect8_CompletedAntecedent_NullContinuation_NoErrors()
        {
            // declaring these makes it clear we are testing the correct overload
            Task<string> antecedent = CompletedTask.FromResult("Test string");
            Action<Task<string>> continuationAction = null;
            bool supportsErrors = false;

            CoreTaskExtensions.Select(antecedent, continuationAction, supportsErrors);
        }

        /// <summary>
        /// This method test the behavior of the
        /// <see cref="CoreTaskExtensions.Select{TSource}(Task{TSource}, Action{Task{TSource}}, bool)"/>
        /// method.
        /// </summary>
        [TestMethod]
        public void TestSelect8_CompletedAntecedent_CompletedContinuation_NoErrors()
        {
            bool executed = false;

            // declaring these makes it clear we are testing the correct overload
            Task<string> antecedent = CompletedTask.FromResult("Test string");
            Action<Task<string>> continuationAction = task => executed = true;
            bool supportsErrors = false;

            Task combinedTask = CoreTaskExtensions.Select(antecedent, continuationAction, supportsErrors);
            combinedTask.Wait();
            Assert.AreEqual(TaskStatus.RanToCompletion, combinedTask.Status);
            Assert.IsTrue(executed);
        }

        /// <summary>
        /// This method test the behavior of the
        /// <see cref="CoreTaskExtensions.Select{TSource}(Task{TSource}, Action{Task{TSource}}, bool)"/>
        /// method.
        /// </summary>
        [TestMethod]
        public void TestSelect8_CanceledAntecedent_CompletedContinuation_NoErrors()
        {
            bool executed = false;

            // declaring these makes it clear we are testing the correct overload
            Task<string> antecedent = CompletedTask.Canceled<string>();
            Action<Task<string>> continuationAction = task => executed = true;
            bool supportsErrors = false;

            Task combinedTask = null;

            try
            {
                combinedTask = CoreTaskExtensions.Select(antecedent, continuationAction, supportsErrors);
                combinedTask.Wait();
                Assert.Fail("Expected a TaskCanceledException wrapped in an AggregateException");
            }
            catch (AggregateException ex)
            {
                Assert.IsNotNull(combinedTask, "Failed to create the combined task.");
                Assert.AreEqual(TaskStatus.Canceled, combinedTask.Status);
                Assert.AreEqual(1, ex.InnerExceptions.Count);
                Assert.IsInstanceOfType(ex.InnerExceptions[0], typeof(TaskCanceledException));
                Assert.IsFalse(executed);
            }
        }

        /// <summary>
        /// This method test the behavior of the
        /// <see cref="CoreTaskExtensions.Select{TSource}(Task{TSource}, Action{Task{TSource}}, bool)"/>
        /// method.
        /// </summary>
        [TestMethod]
        public void TestSelect8_FaultedAntecedent_CompletedContinuation_NoErrors()
        {
            bool executed = false;

            // declaring these makes it clear we are testing the correct overload
            TaskCompletionSource<string> faultedCompletionSource = new TaskCompletionSource<string>();
            Exception expectedException = new ArgumentException();
            faultedCompletionSource.SetException(expectedException);
            Task<string> antecedent = faultedCompletionSource.Task;
            Action<Task<string>> continuationAction = task => executed = true;
            bool supportsErrors = false;

            Task combinedTask = null;

            try
            {
                combinedTask = CoreTaskExtensions.Select(antecedent, continuationAction, supportsErrors);
                combinedTask.Wait();
                Assert.Fail("Expected an ArgumentException wrapped in an AggregateException");
            }
            catch (AggregateException ex)
            {
                Assert.IsNotNull(combinedTask, "Failed to create the combined task.");
                Assert.AreEqual(TaskStatus.Faulted, combinedTask.Status);
                Assert.AreEqual(1, ex.InnerExceptions.Count);
                Assert.AreSame(expectedException, ex.InnerExceptions[0]);
                Assert.IsFalse(executed);
            }
        }

        /// <summary>
        /// This method test the behavior of the
        /// <see cref="CoreTaskExtensions.Select{TSource}(Task{TSource}, Action{Task{TSource}}, bool)"/>
        /// method.
        /// </summary>
        [TestMethod]
        public void TestSelect8_CompletedAntecedent_FaultedContinuation_NoErrors()
        {
            bool executed = false;

            // declaring these makes it clear we are testing the correct overload
            Task<string> antecedent = CompletedTask.FromResult("Test string");

            Exception continuationException = new InvalidOperationException();
            Action<Task<string>> continuationAction = task =>
                {
                    executed = true;
                    throw continuationException;
                };

            bool supportsErrors = false;

            Task combinedTask = null;

            try
            {
                combinedTask = CoreTaskExtensions.Select(antecedent, continuationAction, supportsErrors);
                combinedTask.Wait();
                Assert.Fail("Expected an InvalidOperationException wrapped in an AggregateException");
            }
            catch (AggregateException ex)
            {
                Assert.IsNotNull(combinedTask, "Failed to create the combined task.");
                Assert.AreEqual(TaskStatus.Faulted, combinedTask.Status);
                Assert.AreEqual(1, ex.InnerExceptions.Count);
                Assert.AreSame(continuationException, ex.InnerExceptions[0]);
                Assert.IsTrue(executed);
            }
        }

        /// <summary>
        /// This method test the behavior of the
        /// <see cref="CoreTaskExtensions.Select{TSource}(Task{TSource}, Action{Task{TSource}}, bool)"/>
        /// method.
        /// </summary>
        [TestMethod]
        public void TestSelect8_CanceledAntecedent_FaultedContinuation_NoErrors()
        {
            bool executed = false;

            // declaring these makes it clear we are testing the correct overload
            Task<string> antecedent = CompletedTask.Canceled<string>();

            Exception continuationException = new InvalidOperationException();
            Action<Task<string>> continuationAction = task =>
                {
                    executed = true;
                    throw continuationException;
                };

            bool supportsErrors = false;

            Task combinedTask = null;

            try
            {
                combinedTask = CoreTaskExtensions.Select(antecedent, continuationAction, supportsErrors);
                combinedTask.Wait();
                Assert.Fail("Expected a TaskCanceledException wrapped in an AggregateException");
            }
            catch (AggregateException ex)
            {
                Assert.IsNotNull(combinedTask, "Failed to create the combined task.");
                Assert.AreEqual(TaskStatus.Canceled, combinedTask.Status);
                Assert.AreEqual(1, ex.InnerExceptions.Count);
                Assert.IsInstanceOfType(ex.InnerExceptions[0], typeof(TaskCanceledException));
                Assert.IsFalse(executed);
            }
        }

        /// <summary>
        /// This method test the behavior of the
        /// <see cref="CoreTaskExtensions.Select{TSource}(Task{TSource}, Action{Task{TSource}}, bool)"/>
        /// method.
        /// </summary>
        [TestMethod]
        public void TestSelect8_FaultedAntecedent_FaultedContinuation_NoErrors()
        {
            bool executed = false;

            // declaring these makes it clear we are testing the correct overload
            TaskCompletionSource<string> faultedCompletionSource = new TaskCompletionSource<string>();
            Exception expectedException = new ArgumentException();
            faultedCompletionSource.SetException(expectedException);
            Task<string> antecedent = faultedCompletionSource.Task;

            Exception continuationException = new InvalidOperationException();
            Action<Task<string>> continuationAction = task =>
                {
                    executed = true;
                    throw continuationException;
                };

            bool supportsErrors = false;

            Task combinedTask = null;

            try
            {
                combinedTask = CoreTaskExtensions.Select(antecedent, continuationAction, supportsErrors);
                combinedTask.Wait();
                Assert.Fail("Expected an ArgumentException wrapped in an AggregateException");
            }
            catch (AggregateException ex)
            {
                Assert.IsNotNull(combinedTask, "Failed to create the combined task.");
                Assert.AreEqual(TaskStatus.Faulted, combinedTask.Status);
                Assert.AreEqual(1, ex.InnerExceptions.Count);
                Assert.AreSame(expectedException, ex.InnerExceptions[0]);
                Assert.IsFalse(executed);
            }
        }

        /// <summary>
        /// This method test the behavior of the
        /// <see cref="CoreTaskExtensions.Select{TSource}(Task{TSource}, Action{Task{TSource}}, bool)"/>
        /// method.
        /// </summary>
        [TestMethod]
        [ExpectedException(typeof(ArgumentNullException))]
        public void TestSelect8_NullAntecedent_CompletedContinuation_SupportsErrors()
        {
            // declaring these makes it clear we are testing the correct overload
            Task<string> antecedent = null;
            Action<Task<string>> continuationAction = task =>
                {
                };
            bool supportsErrors = true;

            CoreTaskExtensions.Select(antecedent, continuationAction, supportsErrors);
        }

        /// <summary>
        /// This method test the behavior of the
        /// <see cref="CoreTaskExtensions.Select{TSource}(Task{TSource}, Action{Task{TSource}}, bool)"/>
        /// method.
        /// </summary>
        [TestMethod]
        [ExpectedException(typeof(ArgumentNullException))]
        public void TestSelect8_CompletedAntecedent_NullContinuation_SupportsErrors()
        {
            // declaring these makes it clear we are testing the correct overload
            Task<string> antecedent = CompletedTask.FromResult("Test string");
            Action<Task<string>> continuationAction = null;
            bool supportsErrors = true;

            CoreTaskExtensions.Select(antecedent, continuationAction, supportsErrors);
        }

        /// <summary>
        /// This method test the behavior of the
        /// <see cref="CoreTaskExtensions.Select{TSource}(Task{TSource}, Action{Task{TSource}}, bool)"/>
        /// method.
        /// </summary>
        [TestMethod]
        public void TestSelect8_CompletedAntecedent_CompletedContinuation_SupportsErrors()
        {
            bool executed = false;

            // declaring these makes it clear we are testing the correct overload
            Task<string> antecedent = CompletedTask.FromResult("Test string");
            Action<Task<string>> continuationAction = task => executed = true;
            bool supportsErrors = true;

            Task combinedTask = CoreTaskExtensions.Select(antecedent, continuationAction, supportsErrors);
            combinedTask.Wait();
            Assert.AreEqual(TaskStatus.RanToCompletion, combinedTask.Status);
            Assert.IsTrue(executed);
        }

        /// <summary>
        /// This method test the behavior of the
        /// <see cref="CoreTaskExtensions.Select{TSource}(Task{TSource}, Action{Task{TSource}}, bool)"/>
        /// method.
        /// </summary>
        [TestMethod]
        public void TestSelect8_CanceledAntecedent_CompletedContinuation_SupportsErrors()
        {
            bool executed = false;

            // declaring these makes it clear we are testing the correct overload
            Task<string> antecedent = CompletedTask.Canceled<string>();
            Action<Task<string>> continuationAction = task => executed = true;
            bool supportsErrors = true;

            Task combinedTask = null;

            try
            {
                combinedTask = CoreTaskExtensions.Select(antecedent, continuationAction, supportsErrors);
                combinedTask.Wait();
                Assert.Fail("Expected a TaskCanceledException wrapped in an AggregateException");
            }
            catch (AggregateException ex)
            {
                Assert.IsNotNull(combinedTask, "Failed to create the combined task.");
                Assert.AreEqual(TaskStatus.Canceled, combinedTask.Status);
                Assert.AreEqual(1, ex.InnerExceptions.Count);
                Assert.IsInstanceOfType(ex.InnerExceptions[0], typeof(TaskCanceledException));
                Assert.IsFalse(executed);
            }
        }

        /// <summary>
        /// This method test the behavior of the
        /// <see cref="CoreTaskExtensions.Select{TSource}(Task{TSource}, Action{Task{TSource}}, bool)"/>
        /// method.
        /// </summary>
        [TestMethod]
        public void TestSelect8_FaultedAntecedent_CompletedContinuation_SupportsErrors()
        {
            bool executed = false;

            // declaring these makes it clear we are testing the correct overload
            TaskCompletionSource<string> faultedCompletionSource = new TaskCompletionSource<string>();
            Exception expectedException = new ArgumentException();
            faultedCompletionSource.SetException(expectedException);
            Task<string> antecedent = faultedCompletionSource.Task;
            Action<Task<string>> continuationAction = task => executed = true;
            bool supportsErrors = true;

            Task combinedTask = CoreTaskExtensions.Select(antecedent, continuationAction, supportsErrors);
            combinedTask.Wait();
            Assert.AreEqual(TaskStatus.RanToCompletion, combinedTask.Status);
            Assert.IsTrue(executed);
        }

        /// <summary>
        /// This method test the behavior of the
        /// <see cref="CoreTaskExtensions.Select{TSource}(Task{TSource}, Action{Task{TSource}}, bool)"/>
        /// method.
        /// </summary>
        [TestMethod]
        public void TestSelect8_CompletedAntecedent_FaultedContinuation_SupportsErrors()
        {
            bool executed = false;

            // declaring these makes it clear we are testing the correct overload
            Task<string> antecedent = CompletedTask.FromResult("Test string");

            Exception continuationException = new InvalidOperationException();
            Action<Task<string>> continuationAction = task =>
                {
                    executed = true;
                    throw continuationException;
                };

            bool supportsErrors = true;

            Task combinedTask = null;

            try
            {
                combinedTask = CoreTaskExtensions.Select(antecedent, continuationAction, supportsErrors);
                combinedTask.Wait();
                Assert.Fail("Expected an InvalidOperationException wrapped in an AggregateException");
            }
            catch (AggregateException ex)
            {
                Assert.IsNotNull(combinedTask, "Failed to create the combined task.");
                Assert.AreEqual(TaskStatus.Faulted, combinedTask.Status);
                Assert.AreEqual(1, ex.InnerExceptions.Count);
                Assert.AreSame(continuationException, ex.InnerExceptions[0]);
                Assert.IsTrue(executed);
            }
        }

        /// <summary>
        /// This method test the behavior of the
        /// <see cref="CoreTaskExtensions.Select{TSource}(Task{TSource}, Action{Task{TSource}}, bool)"/>
        /// method.
        /// </summary>
        [TestMethod]
        public void TestSelect8_CanceledAntecedent_FaultedContinuation_SupportsErrors()
        {
            bool executed = false;

            // declaring these makes it clear we are testing the correct overload
            Task<string> antecedent = CompletedTask.Canceled<string>();

            Exception continuationException = new InvalidOperationException();
            Action<Task<string>> continuationAction = task =>
                {
                    executed = true;
                    throw continuationException;
                };

            bool supportsErrors = true;

            Task combinedTask = null;

            try
            {
                combinedTask = CoreTaskExtensions.Select(antecedent, continuationAction, supportsErrors);
                combinedTask.Wait();
                Assert.Fail("Expected a TaskCanceledException wrapped in an AggregateException");
            }
            catch (AggregateException ex)
            {
                Assert.IsNotNull(combinedTask, "Failed to create the combined task.");
                Assert.AreEqual(TaskStatus.Canceled, combinedTask.Status);
                Assert.AreEqual(1, ex.InnerExceptions.Count);
                Assert.IsInstanceOfType(ex.InnerExceptions[0], typeof(TaskCanceledException));
                Assert.IsFalse(executed);
            }
        }

        /// <summary>
        /// This method test the behavior of the
        /// <see cref="CoreTaskExtensions.Select{TSource}(Task{TSource}, Action{Task{TSource}}, bool)"/>
        /// method.
        /// </summary>
        [TestMethod]
        public void TestSelect8_FaultedAntecedent_FaultedContinuation_SupportsErrors()
        {
            bool executed = false;

            // declaring these makes it clear we are testing the correct overload
            TaskCompletionSource<string> faultedCompletionSource = new TaskCompletionSource<string>();
            Exception expectedException = new ArgumentException();
            faultedCompletionSource.SetException(expectedException);
            Task<string> antecedent = faultedCompletionSource.Task;

            Exception continuationException = new InvalidOperationException();
            Action<Task<string>> continuationAction = task =>
                {
                    executed = true;
                    throw continuationException;
                };

            bool supportsErrors = true;

            Task combinedTask = null;

            try
            {
                combinedTask = CoreTaskExtensions.Select(antecedent, continuationAction, supportsErrors);
                combinedTask.Wait();
                Assert.Fail("Expected an InvalidOperationException wrapped in an AggregateException");
            }
            catch (AggregateException ex)
            {
                Assert.IsNotNull(combinedTask, "Failed to create the combined task.");
                Assert.AreEqual(TaskStatus.Faulted, combinedTask.Status);
                Assert.AreEqual(1, ex.InnerExceptions.Count);
                Assert.AreSame(continuationException, ex.InnerExceptions[0]);
                Assert.IsTrue(executed);
            }
        }

        #endregion
    }
}
